Workbook

Sheet Matrik Stakeholder
B1: Sikap | L1: Pengetahuan | Q1: Keterampilan | U1: Total
B2: 1 | C2: 2 | D2: 3 | E2: 4 | F2: 5 | G2: 6 | H2: 7 | I2: 8 | J2: 9 | K2: 10 | L2: 1 | M2: 2 | N2: 3 | O2: 4 | P2: 5 | Q2: 1 | R2: 2 | S2: 3 | T2: 4 | W2: SKOR SKP
A3: 1 | B3: 4 | C3: 3 | D3: 3 | E3: 3 | F3: 3 | G3: 4 | H3: 3 | I3: 3 | J3: 3 | K3: 4 | L3: 4 | M3: 4 | N3: 4 | O3: 4 | P3: 4 | Q3: 4 | R3: 4 | S3: 4 | T3: 4 | U3: =SUM(B3:T3) -> 69 | W3: S | X3: =B12+C12+E12+J12+K12 -> 130
A4: 2 | B4: 4 | C4: 4 | D4: 4 | E4: 4 | F4: 4 | G4: 4 | H4: 4 | I4: 4 | J4: 4 | K4: 4 | L4: 4 | M4: 4 | N4: 4 | O4: 4 | P4: 4 | Q4: 3 | R4: 3 | S4: 3 | T4: 2 | U4: =SUM(B4:T4) -> 71 | W4: P | X4: =SUM(L12:P12)+0.6*(D12+F12+G12+H12+I12) -> 186.4
A5: 3 | B5: 4 | C5: 4 | D5: 4 | E5: 4 | F5: 4 | G5: 4 | H5: 4 | I5: 4 | J5: 4 | K5: 4 | L5: 4 | M5: 4 | N5: 4 | O5: 4 | P5: 4 | Q5: 3 | R5: 3 | S5: 3 | T5: 2 | U5: =SUM(B5:T5) -> 71 | W5: K | X5: =SUM(Q12:T12)+0.4*(D12+F12+G12+H12+I12) -> 145.6
A6: 4 | B6: 4 | C6: 4 | D6: 4 | E6: 4 | F6: 4 | G6: 4 | H6: 4 | I6: 4 | J6: 4 | K6: 4 | L6: 3 | M6: 3 | N6: 3 | O6: 3 | P6: 4 | Q6: 4 | R6: 4 | S6: 4 | T6: 3 | U6: =SUM(B6:T6) -> 71
A7: 5 | B7: 4 | C7: 4 | D7: 4 | E7: 4 | F7: 4 | G7: 4 | H7: 4 | I7: 4 | J7: 4 | K7: 4 | L7: 2 | M7: 2 | N7: 2 | O7: 2 | P7: 4 | Q7: 1 | R7: 1 | S7: 1 | T7: 3 | U7: =SUM(B7:T7) -> 58
A8: 6 | B8: 1 | C8: 1 | D8: 1 | E8: 1 | F8: 1 | G8: 1 | H8: 1 | I8: 1 | J8: 1 | K8: 1 | L8: 0 | M8: 0 | N8: 0 | O8: 0 | P8: 0 | Q8: 3 | R8: 3 | S8: 4 | T8: 3 | U8: =SUM(B8:T8) -> 23
A9: 7 | B9: 4 | C9: 2 | D9: 3 | E9: 3 | F9: 2 | G9: 4 | H9: 2 | I9: 3 | J9: 1 | K9: 4 | L9: 2 | M9: 2 | N9: 2 | O9: 2 | P9: 0 | Q9: 3 | R9: 3 | S9: 3 | T9: 0 | U9: =SUM(B9:T9) -> 45
A10: 8 | B10: 4 | C10: 2 | D10: 3 | E10: 3 | F10: 2 | G10: 4 | H10: 2 | I10: 3 | J10: 1 | K10: 4 | L10: 2 | M10: 2 | N10: 2 | O10: 2 | P10: 3 | Q10: 3 | R10: 3 | S10: 3 | T10: 0 | U10: =SUM(B10:T10) -> 48
A11: 9 | B11: 0 | C11: 0 | D11: 0 | E11: 0 | F11: 0 | G11: 0 | H11: 0 | I11: 0 | J11: 0 | K11: 0 | L11: 0 | M11: 0 | N11: 0 | O11: 0 | P11: 2 | Q11: 0 | R11: 0 | S11: 0 | T11: 4 | U11: =SUM(B11:T11) -> 6
A12: Total | B12: =SUM(B3:B11) -> 29 | C12: =SUM(C3:C11) -> 24 | D12: =SUM(D3:D11) -> 26 | E12: =SUM(E3:E11) -> 26 | F12: =SUM(F3:F11) -> 24 | G12: =SUM(G3:G11) -> 29 | H12: =SUM(H3:H11) -> 24 | I12: =SUM(I3:I11) -> 26 | ... U12: =SUM(U3:U11) -> 462

Sheet MK Lama
A1: Kompetensi | B1: Mata Kuliah
A2: Kompetensi Inti Keilmuan | B2: Pengantar Ekonomi Mikro
B3: Pengantar Ekonomi Makro
B4: Teori Ekonomi Mikro 1
B5: Teori Ekonomi Makro 1
B6: Teori Ekonomi Mikro II
B7: Teori Ekonomi Makro II
A8: Kompetensi Kuantitatif | B8: Matematika Ekonomi
B9: Matematika Ekonomi Lanjutan
B10: Statistika Ekonomi
B11: Statistika Ekonomi Lanjutan
B12: Ekonometrika 1
B13: Ekonometrika Lanjutan
A14: Kompetensi Kekhususan Dasar | B14: Ekonomi Pembangunan
B15: Ekonomi Moneter
B16: Ekonomi Internasional
B17: Sejarah Pemikiran Ekonomi
B18: Ekonomi Kependudukan & SDM
B19: Metode Penelitian
B20: Ekonomi Publik
B21: Ekonomi SDA & Lingkungan
B22: Perencanaan Pembangunan
A23: Kompetensi Keahlian | B23: Ekonomi Islam
B24: Akuntansi Lembaga Keuangan Syariah
B25: LEMBAGA KEUANGAN ISLAM
B26: Ushul Fiqh Rekayasa Keuangan
B27: Metode Pengambilan Keputusan
B28: Ekonomi Regional
B29: Studi Kelayakan
B30: Kewirausahaan
B31: Komunikasi Pembangunan
B32: Komunikasi Bisnis
B33: Ekonomi Politik dan Kelembagaan
B34: Ekonomi Manajerial
B35: Manajemen Risiko Lembaga Keuangan
... B50: Skripsi / Karya Tulis Ilmiah
A51: Kompetensi Penunjang | B51: Pancasila
B52: Pend. Kewarganegaraan
B53: Pengantar Akuntansi
B54: Lab Informasi dan Teknologi
...

Sheet BK
A1: 1. Fondasi Teori Ekonomi | B1: (P1) | D1: No | E1: Bahan Kajian | F1: Substansi Kajian | G1: Statement Bahan Kajian | H1: CPL Terkait
A2: 2. Analisis Data & Metodologi | B2: (P2 + KK1 + KK3) | D2: 1 | E2: Fondasi Teori Ekonomi Pembangunan | F2: Teori mikro, makro, dan pembangunan; teori pertumbuhan; indikator pembangunan | G2: Menganalisis, mengevaluasi, dan mensintesis teori ekonomi untuk menjelaskan fenomena pembangunan secara komprehensif, serta menginterpretasikan indikator ekonomi sebagai dasar pengambilan keputusan. | H2: P1, KU1, KK1
A3: 3. Kebijakan & Pembangunan | B3: (P3 + KK2) | D3: 2 | E3: Analisis Data dan Metodologi Ekonomi | F3: Metode penelitian; statistik; ekonometrika; data analytics | G3: Merancang penelitian, mengelola dan menganalisis data ekonomi secara sistematis, serta menghasilkan inferensi dan rekomendasi berbasis bukti untuk mendukung pengambilan keputusan. | H3: P2, KK1, KK3, KU3, KU4
A4: 4. Ekonomi Islam & Etika | B4: (P4) | D4: 3 | E4: Analisis Masalah Pembangunan dan Kebijakan | F4: Kebijakan publik; evaluasi kebijakan; perencanaan pembangunan | G4: Mengidentifikasi, menganalisis, dan mengevaluasi permasalahan pembangunan, serta merumuskan alternatif kebijakan berbasis data dan bukti empiris. | H4: P3, KK2, KU3
A5: 5. Inovasi & Kewirausahaan Sosial | B5: (KK4) | D5: 4 | E5: Ekonomi Islam dan Etika Pembangunan | F5: Maqashid al-shariah; fiqih muamalat; etika ekonomi; keuangan sosial Islam | G5: Menganalisis dan mengintegrasikan nilai-nilai Islam dan etika dalam pengambilan keputusan ekonomi, serta mengevaluasi kebijakan pembangunan berdasarkan prinsip keadilan dan kemaslahatan. | H5: P4, S1–S4, KK2
A6: 6. Keterampilan Profesional | B6: (KU) | D6: 5 | E6: Ekonomi Lingkungan dan Keberlanjutan | F6: Ekonomi SDA; eksternalitas; pembangunan berkelanjutan | G6: Menganalisis keterkaitan ekonomi dan lingkungan secara sistemik, serta merancang solusi pembangunan berkelanjutan berbasis pendekatan ilmiah dan data. | H6: P3, KK2, S2
D7: 6 | E7: Ekonomi Regional dan Sektoral | F7: Ekonomi regional; perdesaan; perkotaan; struktur sektor | G7: Menganalisis dinamika ekonomi wilayah dan sektor secara komprehensif, serta merumuskan strategi pembangunan berbasis potensi lokal dan data empiris. | H7: P3, KK1, KK4
D8: 7 | E8: Inovasi dan Kewirausahaan Sosial | F8: Social entrepreneurship; inovasi; ekonomi digital | G8: Mengembangkan dan mengevaluasi solusi inovatif berbasis kewirausahaan sosial untuk menjawab permasalahan pembangunan secara kreatif dan berkelanjutan. | H8: KK4, KU2, KU3, S4
D11: No | E11: Mata Kuliah | F11: Bahan Kajian Utama | G11: Bahan Kajian Pendukung
D12: 1 | E12: Pengantar Ekonomi Mikro | F12: Fondasi Teori Ekonomi | G12: -
D13: 2 | E13: Pengantar Ekonomi Makro | F13: Fondasi Teori Ekonomi | G13: -
D14: 3 | E14: Teori Ekonomi Mikro 1 | F14: Fondasi Teori Ekonomi | G14: Analisis Kebijakan
D15: 4 | E15: Teori Ekonomi Mikro II | F15: Fondasi Teori Ekonomi | G15: -
D16: 5 | E16: Teori Ekonomi Makro 1 | F16: Fondasi Teori Ekonomi | G16: -
D17: 6 | E17: Teori Ekonomi Makro II | F17: Fondasi Teori Ekonomi | G17: Analisis Kebijakan
D18: 7 | E18: Sejarah Pemikiran Ekonomi | F18: Fondasi Teori Ekonomi | G18: Etika Ekonomi
D19: 8 | E19: Matematika Ekonomi | F19: Metodologi & Analisis Data | G19: -
D20: 9 | E20: Matematika Ekonomi Lanjutan | F20: Metodologi & Analisis Data | G20: -
D21: 10 | E21: Statistika Ekonomi | F21: Metodologi & Analisis Data | G21: -
D22: 11 | E22: Statistika Ekonomi Lanjutan | F22: Metodologi & Analisis Data | G22: -
D23: 12 | E23: Ekonometrika 1 | F23: Metodologi & Analisis Data | G23: -
... D75: 64 | E75: Islam Disiplin Ilmu | F75: Ekonomi Islam & Etika | G75: Semua BK

Sheet CPL BK
A1: CPL | B1: Keywords CPL | C1: Bahan Kajian (Subject Matters) | D1: Rumpun BK
A2: P1 | B2: Konsep & teori mikro, makro, pembangunan | C2: Teori perilaku konsumen & produsen; teori pasar; teori pertumbuhan ekonomi; model pembangunan (klasik–modern) | D2: Teori Ekonomi
A3: P1 | B3: Konsep & teori mikro, makro, pembangunan | C3: Analisis ekonomi regional & global; dinamika ekonomi makro | D3: Ekonomi Regional & Sektoral
A4: P2 | B4: Metodologi & analisis kuantitatif | C4: Metodologi penelitian ekonomi; desain penelitian | D4: Metodologi & Analisis Data
A5: P2 | B5: Metodologi & analisis kuantitatif | C5: Statistik inferensial; ekonometrika (regresi, causal inference) | D5: Metodologi & Analisis Data
A6: P2 | B6: Metodologi & analisis kuantitatif | C6: Big data & digital analytics | D6: Metodologi & Analisis Data
A7: P3 | B7: Kebijakan, syariah, sustainability | C7: Teori kebijakan publik; policy cycle | D7: Ekonomi Pembangunan & Kebijakan
A8: P3 | B8: Kebijakan, syariah, sustainability | C8: Ekonomi syariah (maqashid, distribusi, keuangan sosial Islam) | D8: Ekonomi Islam & Etika
A9: P3 | B9: Kebijakan, syariah, sustainability | C9: Ekonomi lingkungan; pembangunan berkelanjutan; green economy | D9: Ekonomi Lingkungan & Keberlanjutan
A10: P4 | B10: Etika & nilai ekonomi | C10: Filsafat ekonomi Islam; etika ekonomi | D10: Ekonomi Islam & Etika
A11: P4 | B11: Etika & nilai ekonomi | C11: Keadilan distributif; governance & akuntabilitas | D11: Ekonomi Islam & Etika
A12: KK1 | B12: Analisis masalah sosial ekonomi | C12: Problem structuring ekonomi; analytical framework | D12: Ekonomi Pembangunan & Kebijakan
... A28: S1–S4 | B28: Nilai Islam, etika, kemaslahatan | C28: Sustainability ethics | D28: Ekonomi Lingkungan & Keberlanjutan

Sheet Usulan MK
A1: Nomor | B1: MK Usulan
A2: 1 | B2: Akhlak
A3: 2 | B3: Akuntansi LKS
A4: 3 | B4: Analisis Pembiayaan LK
A5: 4 | B5: Aqidah
A6: 5 | B6: Bahasa Indonesia
A7: 6 | B7: Bahasa Inggris
A8: 7 | B8: Creative Thinking & Analytical Data
A9: 8 | B9: *Ekonomi Digital & Platform
A10: 9 | B10: Ekonometrika 1
A11: 10 | B11: Ekonometrika Lanjutan
A12: 11 | B12: Ekonomi Industri
A13: 12 | B13: Ekonomi Internasional
... A67: 66 | B67: Ushul Fiqh Rekayasa Keuangan

Sheet Skoring BK
A1: Bahan Kajian | B1: Skor S | C1: Skor P | D1: Skor K | E1: S (Auto) | F1: P (Auto) | G1: K (Auto)
A2: Fondasi Teori Ekonomi | B2: 1 | C2: 3 | D2: 1 | E2: =B2/(B2+C2+D2) -> 0.2 | F2: =C2/(B2+C2+D2) -> 0.6 | G2: =D2/(B2+C2+D2) -> 0.2
A3: Metodologi & Analisis Data | B3: 1 | C3: 2 | D3: 3 | E3: =B3/(B3+C3+D3) -> 0.16666667 | F3: =C3/(B3+C3+D3) -> 0.33333333 | G3: =D3/(B3+C3+D3) -> 0.5
A4: Analisis Pembangunan & Kebijakan | B4: 2 | C4: 2 | D4: 2 | E4: =B4/(B4+C4+D4) -> 0.33333333 | F4: =C4/(B4+C4+D4) -> 0.33333333 | G4: =D4/(B4+C4+D4) -> 0.33333333
A5: Ekonomi Islam & Etika | B5: 3 | C5: 2 | D5: 1 | E5: =B5/(B5+C5+D5) -> 0.5 | F5: =C5/(B5+C5+D5) -> 0.33333333 | G5: =D5/(B5+C5+D5) -> 0.16666667
A6: Ekonomi Lingkungan & Keberlanjutan | B6: 2 | C6: 2 | D6: 2 | E6: =B6/(B6+C6+D6) -> 0.33333333 | F6: =C6/(B6+C6+D6) -> 0.33333333 | G6: =D6/(B6+C6+D6) -> 0.33333333
A7: Ekonomi Regional & Sektoral | B7: 2 | C7: 3 | D7: 2 | E7: =B7/(B7+C7+D7) -> 0.28571429 | F7: =C7/(B7+C7+D7) -> 0.42857143 | G7: =D7/(B7+C7+D7) -> 0.28571429
A8: Inovasi & Kewirausahaan Sosial | B8: 2 | C8: 1 | D8: 3 | E8: =B8/(B8+C8+D8) -> 0.33333333 | F8: =C8/(B8+C8+D8) -> 0.16666667 | G8: =D8/(B8+C8+D8) -> 0.5
B9: =SUM(B2:B8) -> 13 | C9: =SUM(C2:C8) -> 15 | D9: =SUM(D2:D8) -> 14 | E9: =SUM(E2:E8) -> 2.152381 | F9: =SUM(F2:F8) -> 2.5285714 | G9: =SUM(G2:G8) -> 2.3190476
B10: =B9/SUM($B$9:$D$9) -> 0.30952381 | C10: =C9/SUM($B$9:$D$9) -> 0.35714286 | D10: =D9/SUM($B$9:$D$9) -> 0.33333333 | E10: =E9/SUM($E$9:$G$9) -> 0.30748299 | F10: =F9/SUM($E$9:$G$9) -> 0.36122449 | G10: =G9/SUM($E$9:$G$9) -> 0.33129252

Sheet Monitor
A1: Mata Kuliah Eksisting | B1: MK Usulan | E1: MK Usulan | F1: No | G1: Mata Kuliah | H1: Bahan Kajian Utama | I1: Bahan Kajian Pendukung | J1: S | K1: P | L1: K | N1: No | O1: Mata Kuliah | P1: SKS | Q1: Semester | T1: No | U1: Mata Kuliah | V1: Semester | W1: SKS | Y1: No | Z1: Mata Kuliah | AA1: Materi | AB1: Praktik | AC1: Tugas | AD1: Score | AE1: SKS | AG1: No | AH1: Mata Kuliah | AI1: SKS | AJ1: Semester | AK1: C | AL1: A | AM1: T | AN1: CAT | AP1: No | AQ1: Kode | AR1: Mata Kuliah | AS1: SKS | AT1: Semester | AU1: C | AV1: A | AW1: T | AX1: CAT
A2: Akhlak | B2: Akhlak | E2: Akhlak | F2: 1 | G2: Pengantar Ekonomi Makro | H2: Fondasi Teori Ekonomi | I2: - | J2: ='Skoring BK'!$E$2 -> 0.2 | K2: ='Skoring BK'!$F$2 -> 0.6 | L2: ='Skoring BK'!$G$2 -> 0.2 | N2: 1 | O2: Pengantar Ekonomi Mikro | P2: 3 | Q2: 1 | T2: 1 | U2: Pengantar Ekonomi Mikro | V2: 1 | Y2: 1 | Z2: Pengantar Ekonomi Mikro | AA2: 2 | AB2: 2 | AC2: 2 | AD2: =SUM(AA2:AC2) -> 6 | AE2: 3 | AG2: 1 | AH2: Pengantar Ekonomi Mikro | AI2: 3 | AJ2: 1 | AK2: 2 | AL2: 2 | AM2: 2 | AN2: =SUM(AK2:AM2) -> 6 | AP2: 1 | AR2: Pengantar Ekonomi Mikro | AS2: 3 | AT2: 1 | AU2: 2 | AV2: 2 | AW2: 2 | AX2: =SUM(AU2:AW2) -> 6
A3: Akuntansi Lembaga Keuangan Syariah | B3: Akuntansi LKS | E3: Akuntansi LKS | F3: 2 | G3: Pengantar Bisnis | H3: Fondasi Teori Ekonomi | I3: - | J3: ='Skoring BK'!$E$2 -> 0.2 | K3: ='Skoring BK'!$F$2 -> 0.6 | L3: ='Skoring BK'!$G$2 -> 0.2 | N3: 2 | O3: Pengantar Ekonomi Makro | P3: 3 | Q3: 1 | T3: 2 | U3: Pengantar Ekonomi Makro | V3: 1 | Y3: 2 | Z3: Pengantar Ekonomi Makro | AA3: 2 | AB3: 2 | AC3: 2 | AD3: =SUM(AA3:AC3) -> 6 | AE3: 3 | AG3: 2 | AH3: Pengantar Ekonomi Makro | AI3: 3 | AJ3: 1 | AK3: 2 | AL3: 2 | AM3: 2 | AN3: =SUM(AK3:AM3) -> 6 | AP3: 2 | AR3: Pengantar Ekonomi Makro | AS3: 3 | AT3: 1 | AU3: 2 | AV3: 2 | AW3: 2 | AX3: =SUM(AU3:AW3) -> 6
A4: Analisis Pembiayaan Lembaga Keuangan | B4: Analisis Pembiayaan LK | E4: Analisis Pembiayaan LK | F4: 3 | G4: Teori Ekonomi Makro II | H4: Fondasi Teori Ekonomi | I4: Analisis Kebijakan | J4: ='Skoring BK'!$E$2 -> 0.2 | K4: ='Skoring BK'!$F$2 -> 0.6 | L4: ='Skoring BK'!$G$2 -> 0.2 | N4: 3 | O4: Pengantar Bisnis | P4: 2 | Q4: 1 | T4: 3 | U4: Pengantar Bisnis | V4: 1 | Y4: 3 | Z4: Pengantar Bisnis | AA4: 2 | AB4: 1 | AC4: 2 | AD4: =SUM(AA4:AC4) -> 5 | AE4: 3 | AG4: 3 | AH4: Pengantar Bisnis | AI4: 2 | AJ4: 1 | AK4: 2 | AL4: 1 | AM4: 2 | AN4: =SUM(AK4:AM4) -> 5 | AP4: 3 | AR4: Pengantar Bisnis | AS4: 2 | AT4: 1 | AU4: 2 | AV4: 1 | AW4: 2 | AX4: =SUM(AU4:AW4) -> 5
A5: Aqidah | B5: Aqidah | E5: Aqidah | F5: 4 | G5: Teori Ekonomi Mikro 1 | H5: Fondasi Teori Ekonomi | I5: - | J5: ='Skoring BK'!$E$2 -> 0.2 | K5: ='Skoring BK'!$F$2 -> 0.6 | L5: ='Skoring BK'!$G$2 -> 0.2 | N5: 4 | O5: Matematika Ekonomi | P5: 3 | Q5: 1 | T5: 4 | U5: Matematika Ekonomi | V5: 1 | Y5: 4 | Z5: Matematika Ekonomi | AA5: 3 | AB5: 2 | AC5: 2 | AD5: =SUM(AA5:AC5) -> 7 | AE5: 3 | AG5: 4 | AH5: Matematika Ekonomi | AI5: 3 | AJ5: 1 | AK5: 3 | AL5: 2 | AM5: 2 | AN5: =SUM(AK5:AM5) -> 7 | AP5: 4 | AR5: Matematika Ekonomi | AS5: 3 | AT5: 1 | AU5: 3 | AV5: 2 | AW5: 2 | AX5: =SUM(AU5:AW5) -> 7
A6: Bahasa Indonesia | B6: Bahasa Indonesia | E6: Bahasa Indonesia | F6: 5 | G6: Studi Kelayakan | H6: Fondasi Teori Ekonomi | I6: - | J6: ='Skoring BK'!$E$2 -> 0.2 | K6: ='Skoring BK'!$F$2 -> 0.6 | L6: ='Skoring BK'!$G$2 -> 0.2 | N6: 5 | O6: Bahasa Indonesia | P6: 2 | Q6: 1 | T6: 5 | U6: Bahasa Indonesia | V6: 1 | Y6: 5 | Z6: Bahasa Indonesia | AA6: 1 | AB6: 2 | AC6: 2 | AD6: =SUM(AA6:AC6) -> 5 | AE6: 3 | AG6: 5 | AH6: Bahasa Indonesia | AI6: 2 | AJ6: 1 | AK6: 1 | AL6: 2 | AM6: 2 | AN6: =SUM(AK6:AM6) -> 5 | AP6: 5 | AR6: Bahasa Indonesia | AS6: 2 | AT6: 1 | AU6: 1 | AV6: 2 | AW6: 2 | AX6: =SUM(AU6:AW6) -> 5
A7: Bahasa Inggris | B7: Bahasa Inggris | E7: Bahasa Inggris | F7: 6 | G7: Teori Ekonomi Makro 1 | H7: Fondasi Teori Ekonomi | I7: Analisis Kebijakan | J7: ='Skoring BK'!$E$2 -> 0.2 | K7: ='Skoring BK'!$F$2 -> 0.6 | L7: ='Skoring BK'!$G$2 -> 0.2 | N7: 6 | O7: Aqidah | P7: 2 | Q7: 1 | T7: 6 | U7: Aqidah | V7: 1 | Y7: 6 | Z7: Aqidah | AA7: 2 | AB7: 1 | AC7: 2 | AD7: =SUM(AA7:AC7) -> 5 | AE7: 2 | AG7: 6 | AH7: Aqidah | AI7: 2 | AJ7: 1 | AK7: 2 | AL7: 1 | AM7: 2 | AN7: =SUM(AK7:AM7) -> 5 | AP7: 6 | AR7: Aqidah | AS7: 2 | AT7: 1 | AU7: 2 | AV7: 1 | AW7: 2 | AX7: =SUM(AU7:AW7) -> 5
A8: creative thinking and analitycal data | B8: Creative Thinking & Analytical Data | E8: Behavioral Economics | F8: 7 | G8: Pesantren | H8: Fondasi Teori Ekonomi | I8: Etika Ekonomi | J8: ='Skoring BK'!$E$2 -> 0.2 | K8: ='Skoring BK'!$F$2 -> 0.6 | L8: ='Skoring BK'!$G$2 -> 0.2 | N8: 7 | O8: Akhlak | P8: 2 | Q8: 1 | T8: 7 | U8: Akhlak | V8: 1 | Y8: 7 | Z8: Akhlak | AA8: 2 | AB8: 1 | AC8: 2 | AD8: =SUM(AA8:AC8) -> 5 | AE8: 2 | AG8: 7 | AH8: Akhlak | AI8: 2 | AJ8: 1 | AK8: 2 | AL8: 1 | AM8: 2 | AN8: =SUM(AK8:AM8) -> 5 | AP8: 7 | AR8: Akhlak | AS8: 2 | AT8: 1 | AU8: 2 | AV8: 1 | AW8: 2 | AX8: =SUM(AU8:AW8) -> 5
A9: Digital Marketing | B9: *Ekonomi Digital & Platform | E9: Creative Thinking & Analytical Data | F9: 8 | G9: Manajemen Wakaf & Zakat | H9: Metodologi & Analisis Data | I9: - | J9: ='Skoring BK'!$E$3 -> 0.16666667 | K9: ='Skoring BK'!$F$3 -> 0.33333333 | L9: ='Skoring BK'!$G$3 -> 0.5 | N9: 8 | O9: Pancasila | P9: 2 | Q9: 1 | T9: 8 | U9: Pancasila | V9: 1 | Y9: 8 | Z9: Pancasila | AA9: 2 | AB9: 1 | AC9: 2 | AD9: =SUM(AA9:AC9) -> 5 | AE9: 2 | AG9: 8 | AH9: Pancasila | AI9: 1 | AJ9: 1 | AK9: 2 | AL9: 1 | AM9: 2 | AN9: =SUM(AK9:AM9) -> 5 | AP9: 8 | AR9: Pancasila | AS9: 1 | AT9: 1 | AU9: 2 | AV9: 1 | AW9: 2 | AX9: =SUM(AU9:AW9) -> 5
A10: Ekonometrika 1 | B10: Ekonometrika 1 | E10: Ekonometrika 1 | F10: 9 | G10: Matematika Ekonomi | H10: Metodologi & Analisis Data | I10: - | J10: ='Skoring BK'!$E$3 -> 0.16666667 | K10: ='Skoring BK'!$F$3 -> 0.33333333 | L10: ='Skoring BK'!$G$3 -> 0.5 | N10: 9 | O10: Pesantren | P10: 1 | Q10: 1 | T10: 9 | U10: Pesantren | V10: 1 | Y10: 9 | Z10: Pesantren | AA10: 1 | AB10: 1 | AC10: 1 | AD10: =SUM(AA10:AC10) -> 3 | AE10: 2 | AG10: 9 | AH10: Pesantren | AI10: 1 | AJ10: 1 | AK10: 1 | AL10: 1 | AM10: 1 | AN10: =SUM(AK10:AM10) -> 3 | AP10: 9 | AR10: Pesantren | AS10: 1 | AT10: 2 | AU10: 1 | AV10: 1 | AW10: 1 | AX10: =SUM(AU10:AW10) -> 3
A11: Ekonometrika Lanjutan | B11: Ekonometrika Lanjutan | E11: Ekonometrika Lanjutan | F11: 10 | G11: Sosiologi & Antropologi | H11: Metodologi & Analisis Data | I11: - | J11: ='Skoring BK'!$E$3 -> 0.16666667 | K11: ='Skoring BK'!$F$3 -> 0.33333333 | L11: ='Skoring BK'!$G$3 -> 0.5 | N11: 10 | O11: Statistika Ekonomi | P11: 3 | Q11: 2 | T11: 10 | U11: Statistika Ekonomi | V11: 2 | Y11: 10 | Z11: Statistika Ekonomi | AA11: 3 | AB11: 2 | AC11: 2 | AD11: =SUM(AA11:AC11) -> 7 | AE11: 3 | AG11: 10 | AH11: Statistika Ekonomi | AI11: 3 | AJ11: 2 | AK11: 3 | AL11: 2 | AM11: 2 | AN11: =SUM(AK11:AM11) -> 7 | AP11: 10 | AR11: Statistika Ekonomi | AS11: 3 | AT11: 2 | AU11: 3 | AV11: 2 | AW11: 2 | AX11: =SUM(AU11:AW11) -> 7
A12: Ekonomi Industri | B12: Ekonomi Industri | E12: Ekonomi Digital & Platform | F12: 11 | G12: Statistika Ekonomi | H12: Metodologi & Analisis Data | I12: - | J12: ='Skoring BK'!$E$3 -> 0.16666667 | K12: ='Skoring BK'!$F$3 -> 0.33333333 | L12: ='Skoring BK'!$G$3 -> 0.5 | N12: 11 | O12: Pengantar Akuntansi | P12: 3 | Q12: 2 | T12: 11 | U12: Pengantar Akuntansi | V12: 2 | Y12: 11 | Z12: Pengantar Akuntansi | AA12: 2 | AB12: 2 | AC12: 2 | AD12: =SUM(AA12:AC12) -> 6 | AE12: 3 | AG12: 11 | AH12: Pengantar Akuntansi | AI12: 2 | AJ12: 2 | AK12: 2 | AL12: 2 | AM12: 2 | AN12: =SUM(AK12:AM12) -> 6 | AP12: 11 | AR12: Pengantar Akuntansi | AS12: 2 | AT12: 2 | AU12: 2 | AV12: 2 | AW12: 2 | AX12: =SUM(AU12:AW12) -> 6
A13: Ekonomi Internasional | B13: Ekonomi Internasional | E13: Ekonomi Industri | F13: 12 | G13: Ekonometrika 1 | H13: Metodologi & Analisis Data | I13: - | J13: ='Skoring BK'!$E$3 -> 0.16666667 | K13: ='Skoring BK'!$F$3 -> 0.33333333 | L13: ='Skoring BK'!$G$3 -> 0.5 | N13: 12 | O13: Bahasa Inggris | P13: 2 | Q13: 2 | T13: 12 | U13: Bahasa Inggris | V13: 2 | Y13: 12 | Z13: Bahasa Inggris | AA13: 1 | AB13: 2 | AC13: 2 | AD13: =SUM(AA13:AC13) -> 5 | AE13: 2 | AG13: 12 | AH13: Bahasa Inggris | AI13: 2 | AJ13: 2 | AK13: 1 | AL13: 2 | AM13: 2 | AN13: =SUM(AK13:AM13) -> 5 | AP13: 12 | AR13: Bahasa Inggris | AS13: 2 | AT13: 2 | AU13: 1 | AV13: 2 | AW13: 2 | AX13: =SUM(AU13:AW13) -> 5
A14: Ekonomi Islam | B14: Ekonomi Islam | E14: Ekonomi Internasional | F14: 13 | G14: Ekonometrika Lanjutan | H14: Metodologi & Analisis Data | I14: - | J14: ='Skoring BK'!$E$3 -> 0.16666667 | K14: ='Skoring BK'!$F$3 -> 0.33333333 | L14: ='Skoring BK'!$G$3 -> 0.5 | N14: 13 | O14: Fiqih Muamalat | P14: 2 | Q14: 2 | T14: 13 | U14: Fiqih Muamalat | V14: 2 | Y14: 13 | Z14: Fiqih Muamalat | AA14: 2 | AB14: 1 | AC14: 2 | AD14: =SUM(AA14:AC14) -> 5 | AE14: 2 | AG14: 13 | AH14: Fiqih Muamalat | AI14: 2 | AJ14: 2 | AK14: 2 | AL14: 1 | AM14: 2 | AN14: =SUM(AK14:AM14) -> 5 | AP14: 13 | AR14: Fiqih Muamalat | AS14: 2 | AT14: 2 | AU14: 2 | AV14: 1 | AW14: 2 | AX14: =SUM(AU14:AW14) -> 5
A15: Ekonomi Kependudukan & SDM | B15: Ekonomi Kependudukan & SDM | E15: Ekonomi Islam | F15: 14 | G15: Matematika Ekonomi Lanjutan | H15: Metodologi & Analisis Data | I15: - | J15: ='Skoring BK'!$E$3 -> 0.16666667 | K15: ='Skoring BK'!$F$3 -> 0.33333333 | L15: ='Skoring BK'!$G$3 -> 0.5 | N15: 14 | O15: Sejarah Perkembangan Islam | P15: 2 | Q15: 2 | T15: 14 | U15: Sejarah Perkembangan Islam | V15: 2 | Y15: 14 | Z15: Sejarah Perkembangan Islam | AA15: 1 | AB15: 1 | AC15: 2 | AD15: =SUM(AA15:AC15) -> 4 | AE15: 2 | AG15: 14 | AH15: Sejarah Perkembangan Islam | AI15: 2 | AJ15: 2 | AK15: 1 | AL15: 1 | AM15: 2 | AN15: =SUM(AK15:AM15) -> 4 | AP15: 14 | AR15: Sejarah Perkembangan Islam | AS15: 2 | AT15: 2 | AU15: 1 | AV15: 1 | AW15: 2 | AX15: =SUM(AU15:AW15) -> 4
A16: Ekonomi Manajerial | B16: Ekonomi Manajerial | E16: Ekonomi Kependudukan & SDM | F16: 15 | G16: Fiqih Muamalat | H16: Metodologi & Analisis Data | I16: Analisis Kebijakan | J16: ='Skoring BK'!$E$3 -> 0.16666667 | K16: ='Skoring BK'!$F$3 -> 0.33333333 | L16: ='Skoring BK'!$G$3 -> 0.5 | N16: 15 | O16: Lab Bahasa Inggris | P16: 1 | Q16: 2 | T16: 15 | U16: Lab Bahasa Inggris | V16: 2 | Y16: 15 | Z16: Lab Bahasa Inggris | AA16: 1 | AB16: 2 | AC16: 1 | AD16: =SUM(AA16:AC16) -> 4 | AE16: 2 | AG16: 15 | AH16: Lab Bahasa Inggris | AI16: 1 | AJ16: 2 | AK16: 1 | AL16: 2 | AM16: 1 | AN16: =SUM(AK16:AM16) -> 4 | AP16: 15 | AR16: Lab Bahasa Inggris | AS16: 1 | AT16: 2 | AU16: 1 | AV16: 2 | AW16: 1 | AX16: =SUM(AU16:AW16) -> 4
A17: Ekonomi Moneter | B17: Ekonomi Moneter | E17: Ekonomi Manajerial | F17: 16 | G17: Creative Thinking & Analytical Data | H17: Metodologi & Analisis Data | I17: Inovasi | J17: ='Skoring BK'!$E$3 -> 0.16666667 | K17: ='Skoring BK'!$F$3 -> 0.33333333 | L17: ='Skoring BK'!$G$3 -> 0.5 | N17: 16 | O17: Sosiologi & Antropologi | P17: 2 | Q17: 2 | T17: 16 | U17: Sosiologi & Antropologi | V17: 2 | Y17: 16 | Z17: Sosiologi & Antropologi | AA17: 2 | AB17: 2 | AC17: 2 | AD17: =SUM(AA17:AC17) -> 6 | AE17: 3 | AG17: 16 | AH17: Sosiologi & Antropologi | AI17: 2 | AJ17: 2 | AK17: 2 | AL17: 2 | AM17: 1 | AN17: =SUM(AK17:AM17) -> 5 | AP17: 16
A18: Ekonomi Pembangunan | B18: Ekonomi Pembangunan | E18: Ekonomi Moneter | F18: 17 | G18: Ekonomi Moneter | H18: Analisis Pembangunan & Kebijakan | I18: - | J18: ='Skoring BK'!$E$4 -> 0.33333333 | K18: ='Skoring BK'!$F$4 -> 0.33333333 | L18: ='Skoring BK'!$G$4 -> 0.33333333 | N18: 17 | O18: Komunikasi Ilmiah | P18: 2 | Q18: 2 | T18: 17 | U18: Komunikasi Ilmiah | V18: 2 | Y18: 17 | Z18: Komunikasi Ilmiah | AA18: 1 | AB18: 2 | AC18: 2 | AD18: =SUM(AA18:AC18) -> 5 | AE18: 2 | AG18: 17 | AH18: Komunikasi Ilmiah | AI18: 2 | AJ18: 2 | AK18: 1 | AL18: 2 | AM18: 2 | AN18: =SUM(AK18:AM18) -> 5 | AP18: 17
A19: Ekonomi Perdesaan | B19: Ekonomi Perdesaan | E19: Ekonomi Pembangunan | F19: 18 | G19: Peradaban Islam | H19: Analisis Pembangunan & Kebijakan | I19: - | J19: ='Skoring BK'!$E$4 -> 0.33333333 | K19: ='Skoring BK'!$F$4 -> 0.33333333 | L19: ='Skoring BK'!$G$4 -> 0.33333333 | N19: 18 | O19: Islam Disiplin Ilmu | P19: 3 | Q19: 2 | T19: 18 | U19: Islam Disiplin Ilmu | V19: 2 | Y19: 18 | Z19: Islam Disiplin Ilmu | AA19: 2 | AB19: 1 | AC19: 2 | AD19: =SUM(AA19:AC19) -> 5 | AE19: 2 | AG19: 18 | AH19: Islam Disiplin Ilmu | AI19: 2 | AJ19: 2 | AK19: 2 | AL19: 1 | AM19: 2 | AN19: =SUM(AK19:AM19) -> 5 | AP19: 18 | AR19: Islam Disiplin Ilmu | AS19: 2 | AT19: 2 | AU19: 2 | AV19: 1 | AW19: 2 | AX19: =SUM(AU19:AW19) -> 5
A20: Ekonomi Perkotaan | B20: Ekonomi Perkotaan | E20: Ekonomi Perdesaan | F20: 19 | G20: Islam Disiplin Ilmu | H20: Analisis Pembangunan & Kebijakan | I20: - | J20: ='Skoring BK'!$E$4 -> 0.33333333 | K20: ='Skoring BK'!$F$4 -> 0.33333333 | L20: ='Skoring BK'!$G$4 -> 0.33333333 | N20: 19 | O20: Teori Ekonomi Mikro 1 | P20: 3 | Q20: 3 | T20: 19 | U20: Teori Ekonomi Mikro 1 | V20: 3 | Y20: 19 | Z20: Teori Ekonomi Mikro 1 | AA20: 3 | AB20: 2 | AC20: 2 | AD20: =SUM(AA20:AC20) -> 7 | AE20: 3 | AG20: 19 | AH20: Teori Ekonomi Mikro 1 | AI20: 3 | AJ20: 3 | AK20: 3 | AL20: 2 | AM20: 2 | AN20: =SUM(AK20:AM20) -> 7 | AP20: 19 | AR20: Teori Ekonomi Mikro 1 | AS20: 3 | AT20: 3 | AU20: 3 | AV20: 2 | AW20: 2 | AX20: =SUM(AU20:AW20) -> 7
A21: Ekonomi Politik dan Kelembagaan | B21: Ekonomi Politik & Kelembagaan | E21: Ekonomi Perkotaan | F21: 20 | G21: Ekonomi Politik & Kelembagaan | H21: Analisis Pembangunan & Kebijakan | I21: - | J21: ='Skoring BK'!$E$4 -> 0.33333333 | K21: ='Skoring BK'!$F$4 -> 0.33333333 | L21: ='Skoring BK'!$G$4 -> 0.33333333 | N21: 20 | O21: Teori Ekonomi Makro 1 | P21: 3 | Q21: 3 | T21: 20 | U21: Teori Ekonomi Makro 1 | V21: 3 | Y21: 20 | Z21: Teori Ekonomi Makro 1 | AA21: 3 | AB21: 2 | AC21: 2 | AD21: =SUM(AA21:AC21) -> 7 | AE21: 3 | AG21: 20 | AH21: Teori Ekonomi Makro 1 | AI21: 3 | AJ21: 3 | AK21: 3 | AL21: 2 | AM21: 2 | AN21: =SUM(AK21:AM21) -> 7 | AP21: 20 | AR21: Teori Ekonomi Makro 1 | AS21: 3 | AT21: 3 | AU21: 3 | AV21: 2 | AW21: 2 | AX21: =SUM(AU21:AW21) -> 7
A22: Ekonomi Publik | B22: Ekonomi Publik | E22: Ekonomi Politik & Kelembagaan | F22: 21 | G22: Ekonomi Perkotaan | H22: Analisis Pembangunan & Kebijakan | I22: - | J22: ='Skoring BK'!$E$4 -> 0.33333333 | K22: ='Skoring BK'!$F$4 -> 0.33333333 | L22: ='Skoring BK'!$G$4 -> 0.33333333 | N22: 21 | O22: Matematika Ekonomi Lanjutan | P22: 3 | Q22: 3 | T22: 21 | U22: Matematika Ekonomi Lanjutan | V22: 3 | Y22: 21 | Z22: Matematika Ekonomi Lanjutan | AA22: 3 | AB22: 3 | AC22: 2 | AD22: =SUM(AA22:AC22) -> 8 | AE22: 3 | AG22: 21 | AH22: Matematika Ekonomi Lanjutan | AI22: 3 | AJ22: 3 | AK22: 3 | AL22: 3 | AM22: 2 | AN22: =SUM(AK22:AM22) -> 8 | AP22: 21 | AR22: Matematika Ekonomi Lanjutan | AS22: 3 | AT22: 3 | AU22: 3 | AV22: 3 | AW22: 2 | AX22: =SUM(AU22:AW22) -> 8
A23: Ekonomi Regional | B23: Ekonomi Regional | E23: Ekonomi Publik | F23: 22 | G23: Lab IT | H23: Analisis Pembangunan & Kebijakan | I23: Etika | J23: ='Skoring BK'!$E$4 -> 0.33333333 | K23: ='Skoring BK'!$F$4 -> 0.33333333 | L23: ='Skoring BK'!$G$4 -> 0.33333333 | N23: 22 | O23: Statistika Ekonomi Lanjutan | P23: 3 | Q23: 3 | T23: 22 | U23: Statistika Ekonomi Lanjutan | V23: 3 | Y23: 22 | Z23: Statistika Ekonomi Lanjutan | AA23: 3 | AB23: 3 | AC23: 2 | AD23: =SUM(AA23:AC23) -> 8 | AE23: 3 | AG23: 22 | AH23: Statistika Ekonomi Lanjutan | AI23: 3 | AJ23: 3 | AK23: 3 | AL23: 3 | AM23: 2 | AN23: =SUM(AK23:AM23) -> 8 | AP23: 22 | AR23: Akuntansi LKS | AS23: 2 | AT23: 3 | AU23: 2 | AV23: 2 | AW23: 2 | AX23: =SUM(AU23:AW23) -> 6
A24: Ekonomi SDA & Lingkungan | B24: Ekonomi SDA & Lingkungan | E24: Ekonomi Regional | F24: 23 | G24: Ekonomi Publik | H24: Ekonomi Regional & Sektoral | I24: - | J24: ='Skoring BK'!$E$7 -> 0.28571429 | K24: ='Skoring BK'!$F$7 -> 0.42857143 | L24: ='Skoring BK'!$G$7 -> 0.28571429 | N24: 23 | O24: Ekonomi Pembangunan | P24: 3 | Q24: 3 | T24: 23 | U24: Ekonomi Pembangunan | V24: 3 | Y24: 23 | Z24: Ekonomi Pembangunan | AA24: 2 | AB24: 2 | AC24: 2 | AD24: =SUM(AA24:AC24) -> 6 | AE24: 3 | AG24: 23 | AH24: Ekonomi Pembangunan | AI24: 3 | AJ24: 3 | AK24: 2 | AL24: 2 | AM24: 2 | AN24: =SUM(AK24:AM24) -> 6 | AP24: 23 | AR24: Ekonomi & Kebijakan Pembangunan | AS24: 3 | AT24: 3 | AU24: 2 | AV24: 2 | AW24: 2 | AX24: =SUM(AU24:AW24) -> 6
A25: Etika Bisnis Islam | B25: Etika Bisnis Islam | E25: Ekonomi SDA & Lingkungan | F25: 24 | G25: Ekonomi Pembangunan | H25: Ekonomi Regional & Sektoral | I25: Inovasi | J25: ='Skoring BK'!$E$7 -> 0.28571429 | K25: ='Skoring BK'!$F$7 -> 0.42857143 | L25: ='Skoring BK'!$G$7 -> 0.28571429 | N25: 24 | O25: Sejarah Pemikiran Ekonomi | P25: 2 | Q25: 3 | T25: 24 | U25: Sejarah Pemikiran Ekonomi | V25: 3 | Y25: 24 | Z25: Sejarah Pemikiran Ekonomi | AA25: 2 | AB25: 1 | AC25: 2 | AD25: =SUM(AA25:AC25) -> 5 | AE25: 2 | AG25: 24 | AH25: Sejarah Pemikiran Ekonomi | AI25: 2 | AJ25: 3 | AK25: 2 | AL25: 1 | AM25: 2 | AN25: =SUM(AK25:AM25) -> 5 | AP25: 24 | AR25: Sejarah Sosial Ekonomi | AS25: 3 | AT25: 3 | AU25: 2 | AV25: 1 | AW25: 2 | AX25: =SUM(AU25:AW25) -> 5
A26: Fiqih Muamalat | B26: Fiqih Muamalat | E26: Etika Bisnis Islam | F26: 25 | G26: Ekonomi Perdesaan | H26: Ekonomi Regional & Sektoral | I26: - | J26: ='Skoring BK'!$E$7 -> 0.28571429 | K26: ='Skoring BK'!$F$7 -> 0.42857143 | L26: ='Skoring BK'!$G$7 -> 0.28571429 | N26: 25 | O26: Peradaban Islam | P26: 2 | Q26: 3 | T26: 25 | U26: Peradaban Islam | V26: 3 | Y26: 25 | Z26: Peradaban Islam | AA26: 2 | AB26: 1 | AC26: 2 | AD26: =SUM(AA26:AC26) -> 5 | AE26: 2 | AG26: 25 | AH26: Peradaban Islam | AI26: 2 | AJ26: 3 | AK26: 2 | AL26: 1 | AM26: 2 | AN26: =SUM(AK26:AM26) -> 5 | AP26: 25 | AR26: Peradaban Islam | AS26: 2 | AT26: 3 | AU26: 2 | AV26: 1 | AW26: 2 | AX26: =SUM(AU26:AW26) -> 5
A27: Indonesian Economy Modelling | B27: Indonesian Economy Modelling | E27: Fiqih Muamalat | F27: 26 | G27: Ekonomi Industri | H27: Ekonomi Regional & Sektoral | I27: - | J27: ='Skoring BK'!$E$7 -> 0.28571429 | K27: ='Skoring BK'!$F$7 -> 0.42857143 | L27: ='Skoring BK'!$G$7 -> 0.28571429 | N27: 26 | O27: Lab IT | P27: 1 | Q27: 3 | T27: 26 | U27: Lab IT | V27: 3 | Y27: 26 | Z27: Lab IT | AA27: 1 | AB27: 3 | AC27: 1 | AD27: =SUM(AA27:AC27) -> 5 | AE27: 2 | AG27: 26 | AH27: Lab IT | AI27: 1 | AJ27: 3 | AK27: 1 | AL27: 3 | AM27: 1 | AN27: =SUM(AK27:AM27) -> 5 | AP27: 26
A28: Industri Perbankan dan LKNB | B28: Industri Perbankan dan LKNB | E28: Indonesian Economy Modelling | F28: 27 | G28: Ekonomi Kependudukan & SDM | H28: Ekonomi Regional & Sektoral | I28: - | J28: ='Skoring BK'!$E$7 -> 0.28571429 | K28: ='Skoring BK'!$F$7 -> 0.42857143 | L28: ='Skoring BK'!$G$7 -> 0.28571429 | N28: 27 | O28: Teori Ekonomi Mikro II | P28: 3 | Q28: 4 | T28: 27 | U28: Teori Ekonomi Mikro II | V28: 4 | Y28: 27 | Z28: Teori Ekonomi Mikro II | AA28: 3 | AB28: 2 | AC28: 2 | AD28: =SUM(AA28:AC28) -> 7 | AE28: 3 | AG28: 27 | AH28: Teori Ekonomi Mikro II | AI28: 3 | AJ28: 4 | AK28: 3 | AL28: 2 | AM28: 2 | AN28: =SUM(AK28:AM28) -> 7 | AP28: 27 | AR28: Teori Ekonomi Mikro II | AS28: 3 | AT28: 4 | AU28: 3 | AV28: 2 | AW28: 2 | AX28: =SUM(AU28:AW28) -> 7
A29: Islam Disiplin Ilmu | B29: Islam Disiplin Ilmu | E29: Industri Perbankan dan LKNB | F29: 28 | G29: Ekonomi Regional | H29: Ekonomi Lingkungan & Keberlanjutan | I29: - | J29: ='Skoring BK'!$E$6 -> 0.33333333 | K29: ='Skoring BK'!$F$6 -> 0.33333333 | L29: ='Skoring BK'!$G$6 -> 0.33333333 | N29: 28 | O29: Teori Ekonomi Makro II | P29: 3 | Q29: 4 | T29: 28 | U29: Teori Ekonomi Makro II | V29: 4 | Y29: 28 | Z29: Teori Ekonomi Makro II | AA29: 3 | AB29: 2 | AC29: 2 | AD29: =SUM(AA29:AC29) -> 7 | AE29: 3 | AG29: 28 | AH29: Teori Ekonomi Makro II | AI29: 3 | AJ29: 4 | AK29: 3 | AL29: 2 | AM29: 2 | AN29: =SUM(AK29:AM29) -> 7 | AP29: 28 | AR29: Teori Ekonomi Makro II | AS29: 3 | AT29: 4 | AU29: 3 | AV29: 2 | AW29: 2 | AX29: =SUM(AU29:AW29) -> 7
A30: Kebijakan Pembangunan | B30: Kebijakan Pembangunan | E30: Islam Disiplin Ilmu | F30: 29 | G30: Ekonomi Digital & Platform | H30: Inovasi & Kewirausahaan Sosial | I30: Data | J30: ='Skoring BK'!$E$8 -> 0.33333333 | K30: ='Skoring BK'!$F$8 -> 0.16666667 | L30: ='Skoring BK'!$G$8 -> 0.5 | N30: 29 | O30: Ekonometrika 1 | P30: 3 | Q30: 4 | T30: 29 | U30: Ekonometrika 1 | V30: 4 | Y30: 29 | Z30: Ekonometrika 1 | AA30: 3 | AB30: 3 | AC30: 3 | AD30: =SUM(AA30:AC30) -> 9 | AE30: 3 | AG30: 29 | AH30: Ekonometrika 1 | AI30: 3 | AJ30: 4 | AK30: 3 | AL30: 3 | AM30: 3 | AN30: =SUM(AK30:AM30) -> 9 | AP30: 29 | AR30: Ekonometrika 1 | AS30: 3 | AT30: 4 | AU30: 3 | AV30: 3 | AW30: 3 | AX30: =SUM(AU30:AW30) -> 9
A31: Kewirausahaan | B31: Kewirausahaan | E31: Kebijakan Pembangunan | F31: 30 | G31: Behavioral Economics | H31: Inovasi & Kewirausahaan Sosial | I31: Analisis Data | J31: ='Skoring BK'!$E$8 -> 0.33333333 | K31: ='Skoring BK'!$F$8 -> 0.16666667 | L31: ='Skoring BK'!$G$8 -> 0.5 | N31: 30 | O31: Ekonomi Publik | P31: 3 | Q31: 4 | T31: 30 | U31: Ekonomi Publik | V31: 4 | Y31: 30 | Z31: Ekonomi Publik | AA31: 2 | AB31: 2 | AC31: 2 | AD31: =SUM(AA31:AC31) -> 6 | AE31: 3 | AG31: 30 | AH31: Ekonomi Publik | AI31: 3 | AJ31: 4 | AK31: 2 | AL31: 2 | AM31: 2 | AN31: =SUM(AK31:AM31) -> 6 | AP31: 30 | AR31: Ekonomi Publik | AS31: 3 | AT31: 4 | AU31: 2 | AV31: 2 | AW31: 2 | AX31: =SUM(AU31:AW31) -> 6
A32: Komunikasi Bisnis | B32: *Komunikasi Ilmiah | E32: Kewirausahaan | F32: 31 | G32: Kebijakan Pembangunan | H32: Inovasi & Kewirausahaan Sosial | I32: - | J32: ='Skoring BK'!$E$8 -> 0.33333333 | K32: ='Skoring BK'!$F$8 -> 0.16666667 | L32: ='Skoring BK'!$G$8 -> 0.5 | N32: 31 | O32: Ekonomi Regional | P32: 3 | Q32: 4 | T32: 31 | U32: Ekonomi Regional | V32: 4 | Y32: 31 | Z32: Ekonomi Regional | AA32: 2 | AB32: 2 | AC32: 2 | AD32: =SUM(AA32:AC32) -> 6 | AE32: 3 | AG32: 31 | AH32: Ekonomi Regional | AI32: 3 | AJ32: 4 | AK32: 2 | AL32: 2 | AM32: 2 | AN32: =SUM(AK32:AM32) -> 6 | AP32: 31 | AR32: Ekonomi Regional & Spasial | AS32: 3 | AT32: 4 | AU32: 2 | AV32: 2 | AW32: 2 | AX32: =SUM(AU32:AW32) -> 6
A33: Komunikasi Pembangunan | B33: *Law & Economics | E33: Komunikasi Ilmiah | F33: 32 | G33: Statistika Ekonomi Lanjutan | H33: Analisis Pembangunan & Kebijakan | I33: Inovasi | J33: ='Skoring BK'!$E$4 -> 0.33333333 | K33: ='Skoring BK'!$F$4 -> 0.33333333 | L33: ='Skoring BK'!$G$4 -> 0.33333333 | N33: 32 | O33: Pendidikan Kewarganegaraan | P33: 2 | Q33: 4 | T33: 32 | U33: Pendidikan Kewarganegaraan | V33: 4 | Y33: 32 | Z33: Pendidikan Kewarganegaraan | AA33: 2 | AB33: 1 | AC33: 2 | AD33: =SUM(AA33:AC33) -> 5 | AE33: 2 | AG33: 32 | AH33: Pendidikan Kewarganegaraan | AI33: 1 | AJ33: 4 | AK33: 2 | AL33: 1 | AM33: 2 | AN33: =SUM(AK33:AM33) -> 5 | AP33: 32 | AR33: Pendidikan Kewarganegaraan | AS33: 1 | AT33: 4 | AU33: 2 | AV33: 1 | AW33: 2 | AX33: =SUM(AU33:AW33) -> 5
A34: Lab Bahasa Inggris | B34: Lab Bahasa Inggris | E34: Lab Bahasa Inggris | F34: 33 | G34: Ekonomi Islam | H34: Ekonomi Islam & Etika | I34: - | J34: ='Skoring BK'!$E$5 -> 0.5 | K34: ='Skoring BK'!$F$5 -> 0.33333333 | L34: ='Skoring BK'!$G$5 -> 0.16666667 | N34: 33 | O34: Creative Thinking & Analytical Data | P34: 3 | Q34: 4 | T34: 33 | U34: Creative Thinking & Analytical Data | V34: 4 | Y34: 33 | Z34: Creative Thinking & Analytical Data | AA34: 2 | AB34: 3 | AC34: 2 | AD34: =SUM(AA34:AC34) -> 7 | AE34: 3 | AG34: 33 | AH34: Creative Thinking & Analytical Data | AI34: 3 | AJ34: 4 | AK34: 2 | AL34: 3 | AM34: 2 | AN34: =SUM(AK34:AM34) -> 7 | AP34: 33 | AR34: Creative Thinking & Analytical Data | AS34: 3 | AT34: 4 | AU34: 2 | AV34: 3 | AW34: 2 | AX34: =SUM(AU34:AW34) -> 7
A35: Lab Informasi dan Teknologi | B35: Lab IT | E35: Lab IT | F35: 34 | G35: Etika Bisnis Islam | H35: Ekonomi Islam & Etika | I35: - | J35: ='Skoring BK'!$E$5 -> 0.5 | K35: ='Skoring BK'!$F$5 -> 0.33333333 | L35: ='Skoring BK'!$G$5 -> 0.16666667 | N35: 34 | O35: Ekonometrika Lanjutan | P35: 3 | Q35: 5 | T35: 34 | U35: Ekonometrika Lanjutan | V35: 5 | Y35: 34 | Z35: Ekonometrika Lanjutan | AA35: 3 | AB35: 3 | AC35: 3 | AD35: =SUM(AA35:AC35) -> 9 | AE35: 3 | AG35: 34 | AH35: Ekonometrika Lanjutan | AI35: 3 | AJ35: 5 | AK35: 3 | AL35: 3 | AM35: 3 | AN35: =SUM(AK35:AM35) -> 9 | AP35: 34 | AR35: Ekonometrika Lanjutan | AS35: 3 | AT35: 5 | AU35: 3 | AV35: 3 | AW35: 3 | AX35: =SUM(AU35:AW35) -> 9
A36: Lembaga Keuangan Islam | B36: Lembaga Keuangan Islam | E36: Law & Economics | F36: 35 | G36: Teori Ekonomi Mikro II | H36: Ekonomi Islam & Etika | I36: Kebijakan | J36: ='Skoring BK'!$E$5 -> 0.5 | K36: ='Skoring BK'!$F$5 -> 0.33333333 | L36: ='Skoring BK'!$G$5 -> 0.16666667 | N36: 35 | O36: Metode Penelitian | P36: 3 | Q36: 5 | T36: 35 | U36: Metode Penelitian | V36: 5 | Y36: 35 | Z36: Metode Penelitian | AA36: 2 | AB36: 3 | AC36: 3 | AD36: =SUM(AA36:AC36) -> 8 | AE36: 3 | AG36: 35 | AH36: Metode Penelitian | AI36: 3 | AJ36: 5 | AK36: 2 | AL36: 3 | AM36: 3 | AN36: =SUM(AK36:AM36) -> 8 | AP36: 35 | AR36: Metode Penelitian | AS36: 3 | AT36: 5 | AU36: 2 | AV36: 3 | AW36: 3 | AX36: =SUM(AU36:AW36) -> 8
A37: Manajemen | B37: Manajemen Keuangan | E37: Lembaga Keuangan Islam | F37: 36 | G37: Ekonomi SDA & Lingkungan | H37: Ekonomi Islam & Etika | I37: - | J37: ='Skoring BK'!$E$5 -> 0.5 | K37: ='Skoring BK'!$F$5 -> 0.33333333 | L37: ='Skoring BK'!$G$5 -> 0.16666667 | N37: 36 | O37: Ekonomi Moneter | P37: 3 | Q37: 5 | T37: 36 | U37: Ekonomi Moneter | V37: 5 | Y37: 36 | Z37: Ekonomi Moneter | AA37: 3 | AB37: 2 | AC37: 2 | AD37: =SUM(AA37:AC37) -> 7 | AE37: 3 | AG37: 36 | AH37: Ekonomi Moneter | AI37: 3 | AJ37: 5 | AK37: 3 | AL37: 2 | AM37: 2 | AN37: =SUM(AK37:AM37) -> 7 | AP37: 36 | AR37: Ekonomi Moneter | AS37: 3 | AT37: 5 | AU37: 3 | AV37: 2 | AW37: 2 | AX37: =SUM(AU37:AW37) -> 7
A38: Manajemen keuangan dan analisis investasi | B38: Manajemen keuangan dan analisis investasi | E38: Manajemen Keuangan | F38: 37 | G38: Manajemen Risiko LK | H38: Ekonomi Islam & Etika | I38: Inovasi | J38: ='Skoring BK'!$E$5 -> 0.5 | K38: ='Skoring BK'!$F$5 -> 0.33333333 | L38: ='Skoring BK'!$G$5 -> 0.16666667 | N38: 37 | O38: Ekonomi Internasional | P38: 3 | Q38: 5 | T38: 37 | U38: Ekonomi Internasional | V38: 5 | Y38: 37 | Z38: Ekonomi Internasional | AA38: 3 | AB38: 2 | AC38: 2 | AD38: =SUM(AA38:AC38) -> 7 | AE38: 3 | AG38: 37 | AH38: Ekonomi Internasional | AI38: 3 | AJ38: 5 | AK38: 3 | AL38: 2 | AM38: 2 | AN38: =SUM(AK38:AM38) -> 7 | AP38: 37 | AR38: Ekonomi Internasional | AS38: 3 | AT38: 5 | AU38: 3 | AV38: 2 | AW38: 2 | AX38: =SUM(AU38:AW38) -> 7
A39: Manajemen Risiko Lembaga Keuangan | B39: Manajemen Risiko LK | E39: Manajemen keuangan dan analisis investasi | F39: 38 | G39: Law & Economics | H39: Ekonomi Islam & Etika | I39: - | J39: ='Skoring BK'!$E$5 -> 0.5 | K39: ='Skoring BK'!$F$5 -> 0.33333333 | L39: ='Skoring BK'!$G$5 -> 0.16666667 | N39: 38 | O39: Ekonomi Kependudukan & SDM | P39: 3 | Q39: 5 | T39: 38 | U39: Ekonomi Kependudukan & SDM | V39: 5 | Y39: 38 | Z39: Ekonomi Kependudukan & SDM | AA39: 2 | AB39: 2 | AC39: 2 | AD39: =SUM(AA39:AC39) -> 6 | AE39: 3 | AG39: 38 | AH39: Ekonomi Kependudukan & SDM | AI39: 3 | AJ39: 5 | AK39: 2 | AL39: 2 | AM39: 2 | AN39: =SUM(AK39:AM39) -> 6 | AP39: 38 | AR39: Ekonomi Kependudukan & SDM | AS39: 3 | AT39: 5 | AU39: 2 | AV39: 2 | AW39: 2 | AX39: =SUM(AU39:AW39) -> 6
A40: Manajemen Wakaf dan Zakat | B40: Manajemen Wakaf & Zakat | E40: Manajemen Risiko LK | F40: 39 | G40: Akuntansi LKS | H40: Ekonomi Islam & Etika | I40: - | J40: ='Skoring BK'!$E$5 -> 0.5 | K40: ='Skoring BK'!$F$5 -> 0.33333333 | L40: ='Skoring BK'!$G$5 -> 0.16666667 | N40: 39 | O40: Ekonomi SDA & Lingkungan | P40: 3 | Q40: 5 | T40: 39 | U40: Ekonomi SDA & Lingkungan | V40: 5 | Y40: 39 | Z40: Ekonomi SDA & Lingkungan | AA40: 2 | AB40: 2 | AC40: 2 | AD40: =SUM(AA40:AC40) -> 6 | AE40: 3 | AG40: 39 | AH40: Ekonomi SDA & Lingkungan | AI40: 3 | AJ40: 5 | AK40: 2 | AL40: 2 | AM40: 2 | AN40: =SUM(AK40:AM40) -> 6 | AP40: 39 | AR40: Ekonomi SDA & Lingkungan | AS40: 3 | AT40: 5 | AU40: 2 | AV40: 2 | AW40: 2 | AX40: =SUM(AU40:AW40) -> 6
...

Sheet BK-MK
A1: No | B1: Rumpun / Bahan Kajian (PBK) | C1: Mata Kuliah Pengampu | D1: CPL Sikap (S) | E1: CPL Pengetahuan (P) | F1: CPL (KU) | G1: CPL (KK) | H1: Peran Bahan Kajian | J1: No | K1: Mata Kuliah | L1: PBK | M1: S | N1: P | O1: KU | P1: KK | Q1: Peran
A2: 1 | C2: Pengantar Ekonomi Mikro | J2: 1 | K2: Pengantar Ekonomi Mikro | L2: Fondasi Teori | M2: - | N2: P1 | O2: KU1 | P2: KK1 | Q2: Pengenalan konsep dasar
A3: 2 | C3: Pengantar Ekonomi Makro | J3: 2 | K3: Pengantar Ekonomi Makro | L3: Fondasi Teori | M3: - | N3: P1 | O3: KU1 | P3: KK1 | Q3: Pengenalan konsep dasar
A4: 3 | C4: Pengantar Bisnis | J4: 3 | K4: Pengantar Bisnis | L4: Fondasi Teori | M4: S4 | N4: P1 | O4: KU1 | P4: - | Q4: Pengenalan konsep dasar
A5: 4 | C5: Matematika Ekonomi | J5: 4 | K5: Matematika Ekonomi | L5: Analisis Data | M5: - | N5: P2 | O5: KU1 | P5: KK1 | Q5: Pengenalan konsep dasar
A6: 5 | C6: Bahasa Indonesia | J6: 5 | K6: Bahasa Indonesia | L6: Komunikasi Ilmiah | M6: S1 | N6: P1 | O6: KU2 | P6: - | Q6: Pengenalan konsep dasar
A7: 6 | C7: PAI 1 (Aqidah) | J7: 6 | K7: PAI 1 (Aqidah) | L7: Nilai Islam | M7: S1-S2 | N7: P4 | O7: - | P7: - | Q7: Pengenalan konsep dasar
A8: 7 | C8: Pendidikan Kewarganegaraan | J8: 7 | K8: Pendidikan Kewarganegaraan | L8: Nilai & Etika | M8: S2-S3 | N8: P1 | O8: KU2 | P8: - | Q8: Pengenalan konsep dasar
A9: 8 | C9: Pancasila | J9: 8 | K9: Pancasila | L9: Nilai & Etika | M9: S2 | N9: P1 | O9: KU2 | P9: - | Q9: Pengenalan konsep dasar
A10: 9 | C10: PAI 2 (Pesantren) | J10: 9 | K10: PAI 2 (Pesantren) | L10: Nilai Islam | M10: S1-S3 | N10: P4 | O10: - | P10: - | Q10: Penguatan dan aplikasi
A11: 10 | C11: Statistika Ekonomi | J11: 10 | K11: Statistika Ekonomi | L11: Analisis Data | M11: - | N11: P2 | O11: KU3 | P11: KK1 | Q11: Pengenalan konsep dasar
A12: 11 | C12: Pengantar Akuntansi | J12: 11 | K12: Pengantar Akuntansi | L12: Pendukung Ekonomi | M12: - | N12: P1 | O12: KU1 | P12: - | Q12: Pengenalan konsep dasar
A13: 12 | C13: Bahasa Inggris | J13: 12 | K13: Bahasa Inggris | L13: Komunikasi | M13: S1 | N13: P1 | O13: KU2 | P13: - | Q13: Pengenalan konsep dasar
... A57: 56 | C57: Skripsi | J57: 56 | K57: Skripsi | L57: Integratif | M57: S1-S4 | N57: P1–P4 | O57: KU1–KU3 | P57: KK1–KK4 | Q57: Penguasaan dan sintesis

Sheet Kalkulator SKS
A1: Mata Kuliah | B1: S | C1: P | D1: KU | E1: KK | F1: wS | G1: wP | H1: wKU | I1: wKK | J1: Score | K1: Norm | L1: SKS Auto | M1: Fixed | N1: Priority | O1: Rank | P1: SKS Final
A2: Pengantar Ekonomi Mikro | B2: 2 | C2: 3 | D2: 3 | E2: 3 | F2: 0.3 | G2: 0.4 | H2: 0.15 | I2: 0.15 | J2: =B2*F2+C2*G2+D2*H2+E2*I2 -> 2.7 | K2: =J2*2 -> 5.4 | L2: =IF(K2<=3,2,IF(K2<=7,3,4)) -> 3 | M2: =IF(OR(A2="Pancasila",A2="Kewarganegaraan",A2="Bahasa Inggris",LEFT(A2,3)="PAI"),"YES","NO") -> NO | N2: =(E2*I2)+(D2*H2)+(C2*G2)+(B2*F2) -> 2.7 | O2: =RANK(N2,N$2:N$57) -> 1 | P2: =IF(M2="YES",L2,IF(O2>40,L2-1,L2)) -> 3
A3: Pengantar Ekonomi Makro | B3: 2 | C3: 3 | D3: 3 | E3: 3 | F3: 0.3 | G3: 0.4 | H3: 0.15 | I3: 0.15 | J3: =B3*F3+C3*G3+D3*H3+E3*I3 -> 2.7 | K3: =J3*2 -> 5.4 | L3: =IF(K3<=3,2,IF(K3<=7,3,4)) -> 3 | M3: =IF(OR(A3="Pancasila",A3="Kewarganegaraan",A3="Bahasa Inggris",LEFT(A3,3)="PAI"),"YES","NO") -> NO | N3: =(E3*I3)+(D3*H3)+(C3*G3)+(B3*F3) -> 2.7 | O3: =RANK(N3,N$2:N$57) -> 1 | P3: =IF(M3="YES",L3,IF(O3>40,L3-1,L3)) -> 3
A4: Pengantar Bisnis | B4: 2 | C4: 3 | D4: 3 | E4: 2 | F4: 0.3 | G4: 0.4 | H4: 0.15 | I4: 0.15 | J4: =B4*F4+C4*G4+D4*H4+E4*I4 -> 2.55 | K4: =J4*2 -> 5.1 | L4: =IF(K4<=3,2,IF(K4<=7,3,4)) -> 3 | M4: =IF(OR(A4="Pancasila",A4="Kewarganegaraan",A4="Bahasa Inggris",LEFT(A4,3)="PAI"),"YES","NO") -> NO | N4: =(E4*I4)+(D4*H4)+(C4*G4)+(B4*F4) -> 2.55 | O4: =RANK(N4,N$2:N$57) -> 45 | P4: =IF(M4="YES",L4,IF(O4>40,L4-1,L4)) -> 2
A5: Matematika Ekonomi | B5: 2 | C5: 3 | D5: 3 | E5: 3 | F5: 0.3 | G5: 0.4 | H5: 0.15 | I5: 0.15 | J5: =B5*F5+C5*G5+D5*H5+E5*I5 -> 2.7 | K5: =J5*2 -> 5.4 | L5: =IF(K5<=3,2,IF(K5<=7,3,4)) -> 3 | M5: =IF(OR(A5="Pancasila",A5="Kewarganegaraan",A5="Bahasa Inggris",LEFT(A5,3)="PAI"),"YES","NO") -> NO | N5: =(E5*I5)+(D5*H5)+(C5*G5)+(B5*F5) -> 2.7 | O5: =RANK(N5,N$2:N$57) -> 1 | P5: =IF(M5="YES",L5,IF(O5>40,L5-1,L5)) -> 3
A6: Bahasa Indonesia | B6: 2 | C6: 2 | D6: 3 | E6: 3 | F6: 0.3 | G6: 0.4 | H6: 0.15 | I6: 0.15 | J6: =B6*F6+C6*G6+D6*H6+E6*I6 -> 2.3 | K6: =J6*2 -> 4.6 | L6: =IF(K6<=3,2,IF(K6<=7,3,4)) -> 3 | M6: =IF(OR(A6="Pancasila",A6="Kewarganegaraan",A6="Bahasa Inggris",LEFT(A6,3)="PAI"),"YES","NO") -> NO | N6: =(E6*I6)+(D6*H6)+(C6*G6)+(B6*F6) -> 2.3 | O6: =RANK(N6,N$2:N$57) -> 46 | P6: =IF(M6="YES",L6,IF(O6>40,L6-1,L6)) -> 2
A7: PAI 1 | B7: 2 | C7: 2 | D7: 1 | E7: 1 | F7: 0.3 | G7: 0.4 | H7: 0.15 | I7: 0.15 | J7: =B7*F7+C7*G7+D7*H7+E7*I7 -> 1.7 | K7: =J7*2 -> 3.4 | L7: =IF(K7<=3,2,IF(K7<=7,3,4)) -> 3 | M7: =IF(OR(A7="Pancasila",A7="Kewarganegaraan",A7="Bahasa Inggris",LEFT(A7,2)="PAI"),"YES","NO") -> NO | N7: =(E7*I7)+(D7*H7)+(C7*G7)+(B7*F7) -> 1.7 | O7: =RANK(N7,N$2:N$57) -> 53 | P7: =IF(M7="YES",L7,IF(O7>40,L7-1,L7)) -> 2
A8: Kewarganegaraan | B8: 2 | C8: 2 | D8: 1 | E8: 1 | F8: 0.3 | G8: 0.4 | H8: 0.15 | I8: 0.15 | J8: =B8*F8+C8*G8+D8*H8+E8*I8 -> 1.7 | K8: =J8*2 -> 3.4 | L8: =IF(K8<=3,2,IF(K8<=7,3,4)) -> 3 | M8: =IF(OR(A8="Pancasila",A8="Kewarganegaraan",A8="Bahasa Inggris",LEFT(A8,2)="PAI"),"YES","NO") -> YES | N8: =(E8*I8)+(D8*H8)+(C8*G8)+(B8*F8) -> 1.7 | O8: =RANK(N8,N$2:N$57) -> 53 | P8: =IF(M8="YES",L8,IF(O8>40,L8-1,L8)) -> 3
A9: Pancasila | B9: 2 | C9: 2 | D9: 1 | E9: 1 | F9: 0.3 | G9: 0.4 | H9: 0.15 | I9: 0.15 | J9: =B9*F9+C9*G9+D9*H9+E9*I9 -> 1.7 | K9: =J9*2 -> 3.4 | L9: =IF(K9<=3,2,IF(K9<=7,3,4)) -> 3 | M9: =IF(OR(A9="Pancasila",A9="Kewarganegaraan",A9="Bahasa Inggris",LEFT(A9,3)="PAI"),"YES","NO") -> YES | N9: =(E9*I9)+(D9*H9)+(C9*G9)+(B9*F9) -> 1.7 | O9: =RANK(N9,N$2:N$57) -> 53 | P9: =IF(M9="YES",L9,IF(O9>40,L9-1,L9)) -> 3
A10: PAI 2 | B10: 2 | C10: 2 | D10: 2 | E10: 2 | F10: 0.3 | G10: 0.4 | H10: 0.15 | I10: 0.15 | J10: =B10*F10+C10*G10+D10*H10+E10*I10 -> 2 | K10: =J10*2 -> 4 | L10: =IF(K10<=3,2,IF(K10<=7,3,4)) -> 3 | M10: =IF(OR(A10="Pancasila",A10="Kewarganegaraan",A10="Bahasa Inggris",LEFT(A10,2)="PAI"),"YES","NO") -> NO | N10: =(E10*I10)+(D10*H10)+(C10*G10)+(B10*F10) -> 2 | O10: =RANK(N10,N$2:N$57) -> 47 | P10: =IF(M10="YES",L10,IF(O10>40,L10-1,L10)) -> 2
A11: Statistika Ekonomi | B11: 2 | C11: 3 | D11: 3 | E11: 3 | F11: 0.3 | G11: 0.4 | H11: 0.15 | I11: 0.15 | J11: =B11*F11+C11*G11+D11*H11+E11*I11 -> 2.7 | K11: =J11*2 -> 5.4 | L11: =IF(K11<=3,2,IF(K11<=7,3,4)) -> 3 | M11: =IF(OR(A11="Pancasila",A11="Kewarganegaraan",A11="Bahasa Inggris",LEFT(A11,3)="PAI"),"YES","NO") -> NO | N11: =(E11*I11)+(D11*H11)+(C11*G11)+(B11*F11) -> 2.7 | O11: =RANK(N11,N$2:N$57) -> 1 | P11: =IF(M11="YES",L11,IF(O11>40,L11-1,L11)) -> 3
A12: Pengantar Akuntansi | B12: 2 | C12: 3 | D12: 3 | E12: 3 | F12: 0.3 | G12: 0.4 | H12: 0.15 | I12: 0.15 | J12: =B12*F12+C12*G12+D12*H12+E12*I12 -> 2.7 | K12: =J12*2 -> 5.4 | L12: =IF(K12<=3,2,IF(K12<=7,3,4)) -> 3 | M12: =IF(OR(A12="Pancasila",A12="Kewarganegaraan",A12="Bahasa Inggris",LEFT(A12,3)="PAI"),"YES","NO") -> NO | N12: =(E12*I12)+(D12*H12)+(C12*G12)+(B12*F12) -> 2.7 | O12: =RANK(N12,N$2:N$57) -> 1 | P12: =IF(M12="YES",L12,IF(O12>40,L12-1,L12)) -> 3
A13: Bahasa Inggris | B13: 2 | C13: 3 | D13: 3 | E13: 3 | F13: 0.3 | G13: 0.4 | H13: 0.15 | I13: 0.15 | J13: =B13*F13+C13*G13+D13*H13+E13*I13 -> 2.7 | K13: =J13*2 -> 5.4 | L13: =IF(K13<=3,2,IF(K13<=7,3,4)) -> 3 | M13: =IF(OR(A13="Pancasila",A13="Kewarganegaraan",A13="Bahasa Inggris",LEFT(A13,3)="PAI"),"YES","NO") -> YES | N13: =(E13*I13)+(D13*H13)+(C13*G13)+(B13*F13) -> 2.7 | O13: =RANK(N13,N$2:N$57) -> 1 | P13: =IF(M13="YES",L13,IF(O13>40,L13-1,L13)) -> 3
A14: Matematika Ekonomi Lanjutan | B14: 2 | C14: 3 | D14: 3 | E14: 3 | F14: 0.3 | G14: 0.4 | H14: 0.15 | I14: 0.15 | J14: =B14*F14+C14*G14+D14*H14+E14*I14 -> 2.7 | K14: =J14*2 -> 5.4 | L14: =IF(K14<=3,2,IF(K14<=7,3,4)) -> 3 | M14: =IF(OR(A14="Pancasila",A14="Kewarganegaraan",A14="Bahasa Inggris",LEFT(A14,3)="PAI"),"YES","NO") -> NO | N14: =(E14*I14)+(D14*H14)+(C14*G14)+(B14*F14) -> 2.7 | O14: =RANK(N14,N$2:N$57) -> 1 | P14: =IF(M14="YES",L14,IF(O14>40,L14-1,L14)) -> 3
A15: Lab Bahasa Inggris | B15: 2 | C15: 1 | D15: 2 | E15: 1 | F15: 0.3 | G15: 0.4 | H15: 0.15 | I15: 0.15 | J15: =B15*F15+C15*G15+D15*H15+E15*I15 -> 1.45 | K15: =J15*2 -> 2.9 | L15: =IF(K15<=3,2,IF(K15<=7,3,4)) -> 2 | M15: =IF(OR(A15="Pancasila",A15="Kewarganegaraan",A15="Bahasa Inggris",LEFT(A15,3)="PAI"),"YES","NO") -> NO | N15: =(E15*I15)+(D15*H15)+(C15*G15)+(B15*F15) -> 1.45 | O15: =RANK(N15,N$2:N$57) -> 56 | P15: =IF(M15="YES",L15,IF(O15>40,L15-1,L15)) -> 1
A16: PAI 3 | B16: 2 | C16: 2 | D16: 2 | E16: 2 | F16: 0.3 | G16: 0.4 | H16: 0.15 | I16: 0.15 | J16: =B16*F16+C16*G16+D16*H16+E16*I16 -> 2 | K16: =J16*2 -> 4 | L16: =IF(K16<=3,2,IF(K16<=7,3,4)) -> 3 | M16: =IF(OR(A16="Pancasila",A16="Kewarganegaraan",A16="Bahasa Inggris",LEFT(A16,2)="PAI"),"YES","NO") -> NO | N16: =(E16*I16)+(D16*H16)+(C16*G16)+(B16*F16) -> 2 | O16: =RANK(N16,N$2:N$57) -> 47 | P16: =IF(M16="YES",L16,IF(O16>40,L16-1,L16)) -> 2
A17: Mikro I | B17: 2 | C17: 3 | D17: 3 | E17: 3 | F17: 0.3 | G17: 0.4 | H17: 0.15 | I17: 0.15 | J17: =B17*F17+C17*G17+D17*H17+E17*I17 -> 2.7 | K17: =J17*2 -> 5.4 | L17: =IF(K17<=3,2,IF(K17<=7,3,4)) -> 3 | M17: =IF(OR(A17="Pancasila",A17="Kewarganegaraan",A17="Bahasa Inggris",LEFT(A17,3)="PAI"),"YES","NO") -> NO | N17: =(E17*I17)+(D17*H17)+(C17*G17)+(B17*F17) -> 2.7 | O17: =RANK(N17,N$2:N$57) -> 1 | P17: =IF(M17="YES",L17,IF(O17>40,L17-1,L17)) -> 3
A18: Makro I | B18: 2 | C18: 3 | D18: 3 | E18: 3 | F18: 0.3 | G18: 0.4 | H18: 0.15 | I18: 0.15 | J18: =B18*F18+C18*G18+D18*H18+E18*I18 -> 2.7 | K18: =J18*2 -> 5.4 | L18: =IF(K18<=3,2,IF(K18<=7,3,4)) -> 3 | M18: =IF(OR(A18="Pancasila",A18="Kewarganegaraan",A18="Bahasa Inggris",LEFT(A18,3)="PAI"),"YES","NO") -> NO | N18: =(E18*I18)+(D18*H18)+(C18*G18)+(B18*F18) -> 2.7 | O18: =RANK(N18,N$2:N$57) -> 1 | P18: =IF(M18="YES",L18,IF(O18>40,L18-1,L18)) -> 3
A19: Akuntansi LKS | B19: 2 | C19: 3 | D19: 3 | E19: 3 | F19: 0.3 | G19: 0.4 | H19: 0.15 | I19: 0.15 | J19: =B19*F19+C19*G19+D19*H19+E19*I19 -> 2.7 | K19: =J19*2 -> 5.4 | L19: =IF(K19<=3,2,IF(K19<=7,3,4)) -> 3 | M19: =IF(OR(A19="Pancasila",A19="Kewarganegaraan",A19="Bahasa Inggris",LEFT(A19,3)="PAI"),"YES","NO") -> NO | N19: =(E19*I19)+(D19*H19)+(C19*G19)+(B19*F19) -> 2.7 | O19: =RANK(N19,N$2:N$57) -> 1 | P19: =IF(M19="YES",L19,IF(O19>40,L19-1,L19)) -> 3
A20: Ekonomi Pembangunan | B20: 2 | C20: 3 | D20: 3 | E20: 3 | F20: 0.3 | G20: 0.4 | H20: 0.15 | I20: 0.15 | J20: =B20*F20+C20*G20+D20*H20+E20*I20 -> 2.7 | K20: =J20*2 -> 5.4 | L20: =IF(K20<=3,2,IF(K20<=7,3,4)) -> 3 | M20: =IF(OR(A20="Pancasila",A20="Kewarganegaraan",A20="Bahasa Inggris",LEFT(A20,3)="PAI"),"YES","NO") -> NO | N20: =(E20*I20)+(D20*H20)+(C20*G20)+(B20*F20) -> 2.7 | O20: =RANK(N20,N$2:N$57) -> 1 | P20: =IF(M20="YES",L20,IF(O20>40,L20-1,L20)) -> 3
A21: Sejarah Ekonomi | B21: 2 | C21: 3 | D21: 3 | E21: 3 | F21: 0.3 | G21: 0.4 | H21: 0.15 | I21: 0.15 | J21: =B21*F21+C21*G21+D21*H21+E21*I21 -> 2.7 | K21: =J21*2 -> 5.4 | L21: =IF(K21<=3,2,IF(K21<=7,3,4)) -> 3 | M21: =IF(OR(A21="Pancasila",A21="Kewarganegaraan",A21="Bahasa Inggris",LEFT(A21,3)="PAI"),"YES","NO") -> NO | N21: =(E21*I21)+(D21*H21)+(C21*G21)+(B21*F21) -> 2.7 | O21: =RANK(N21,N$2:N$57) -> 1 | P21: =IF(M21="YES",L21,IF(O21>40,L21-1,L21)) -> 3
A22: LKS | B22: 2 | C22: 3 | D22: 3 | E22: 3 | F22: 0.3 | G22: 0.4 | H22: 0.15 | I22: 0.15 | J22: =B22*F22+C22*G22+D22*H22+E22*I22 -> 2.7 | K22: =J22*2 -> 5.4 | L22: =IF(K22<=3,2,IF(K22<=7,3,4)) -> 3 | M22: =IF(OR(A22="Pancasila",A22="Kewarganegaraan",A22="Bahasa Inggris",LEFT(A22,3)="PAI"),"YES","NO") -> NO | N22: =(E22*I22)+(D22*H22)+(C22*G22)+(B22*F22) -> 2.7 | O22: =RANK(N22,N$2:N$57) -> 1 | P22: =IF(M22="YES",L22,IF(O22>40,L22-1,L22)) -> 3
A23: PAI 4 | B23: 2 | C23: 2 | D23: 2 | E23: 2 | F23: 0.3 | G23: 0.4 | H23: 0.15 | I23: 0.15 | J23: =B23*F23+C23*G23+D23*H23+E23*I23 -> 2 | K23: =J23*2 -> 4 | L23: =IF(K23<=3,2,IF(K23<=7,3,4)) -> 3 | M23: =IF(OR(A23="Pancasila",A23="Kewarganegaraan",A23="Bahasa Inggris",LEFT(A23,2)="PAI"),"YES","NO") -> NO | N23: =(E23*I23)+(D23*H23)+(C23*G23)+(B23*F23) -> 2 | O23: =RANK(N23,N$2:N$57) -> 47 | P23: =IF(M23="YES",L23,IF(O23>40,L23-1,L23)) -> 2
A24: Mikro II | B24: 2 | C24: 3 | D24: 3 | E24: 3 | F24: 0.3 | G24: 0.4 | H24: 0.15 | I24: 0.15 | J24: =B24*F24+C24*G24+D24*H24+E24*I24 -> 2.7 | K24: =J24*2 -> 5.4 | L24: =IF(K24<=3,2,IF(K24<=7,3,4)) -> 3 | M24: =IF(OR(A24="Pancasila",A24="Kewarganegaraan",A24="Bahasa Inggris",LEFT(A24,3)="PAI"),"YES","NO") -> NO | N24: =(E24*I24)+(D24*H24)+(C24*G24)+(B24*F24) -> 2.7 | O24: =RANK(N24,N$2:N$57) -> 1 | P24: =IF(M24="YES",L24,IF(O24>40,L24-1,L24)) -> 3
A25: Makro II | B25: 2 | C25: 3 | D25: 3 | E25: 3 | F25: 0.3 | G25: 0.4 | H25: 0.15 | I25: 0.15 | J25: =B25*F25+C25*G25+D25*H25+E25*I25 -> 2.7 | K25: =J25*2 -> 5.4 | L25: =IF(K25<=3,2,IF(K25<=7,3,4)) -> 3 | M25: =IF(OR(A25="Pancasila",A25="Kewarganegaraan",A25="Bahasa Inggris",LEFT(A25,3)="PAI"),"YES","NO") -> NO | N25: =(E25*I25)+(D25*H25)+(C25*G25)+(B25*F25) -> 2.7 | O25: =RANK(N25,N$2:N$57) -> 1 | P25: =IF(M25="YES",L25,IF(O25>40,L25-1,L25)) -> 3
A26: Ekonometrika I | B26: 2 | C26: 3 | D26: 3 | E26: 3 | F26: 0.3 | G26: 0.4 | H26: 0.15 | I26: 0.15 | J26: =B26*F26+C26*G26+D26*H26+E26*I26 -> 2.7 | K26: =J26*2 -> 5.4 | L26: =IF(K26<=3,2,IF(K26<=7,3,4)) -> 3 | M26: =IF(OR(A26="Pancasila",A26="Kewarganegaraan",A26="Bahasa Inggris",LEFT(A26,3)="PAI"),"YES","NO") -> NO | N26: =(E26*I26)+(D26*H26)+(C26*G26)+(B26*F26) -> 2.7 | O26: =RANK(N26,N$2:N$57) -> 1 | P26: =IF(M26="YES",L26,IF(O26>40,L26-1,L26)) -> 3
A27: Ekonomi Publik | B27: 2 | C27: 3 | D27: 3 | E27: 3 | F27: 0.3 | G27: 0.4 | H27: 0.15 | I27: 0.15 | J27: =B27*F27+C27*G27+D27*H27+E27*I27 -> 2.7 | K27: =J27*2 -> 5.4 | L27: =IF(K27<=3,2,IF(K27<=7,3,4)) -> 3 | M27: =IF(OR(A27="Pancasila",A27="Kewarganegaraan",A27="Bahasa Inggris",LEFT(A27,3)="PAI"),"YES","NO") -> NO | N27: =(E27*I27)+(D27*H27)+(C27*G27)+(B27*F27) -> 2.7 | O27: =RANK(N27,N$2:N$57) -> 1 | P27: =IF(M27="YES",L27,IF(O27>40,L27-1,L27)) -> 3
A28: Ekonomi Regional | B28: 2 | C28: 3 | D28: 3 | E28: 3 | F28: 0.3 | G28: 0.4 | H28: 0.15 | I28: 0.15 | J28: =B28*F28+C28*G28+D28*H28+E28*I28 -> 2.7 | K28: =J28*2 -> 5.4 | L28: =IF(K28<=3,2,IF(K28<=7,3,4)) -> 3 | M28: =IF(OR(A28="Pancasila",A28="Kewarganegaraan",A28="Bahasa Inggris",LEFT(A28,3)="PAI"),"YES","NO") -> NO | N28: =(E28*I28)+(D28*H28)+(C28*G28)+(B28*F28) -> 2.7 | O28: =RANK(N28,N$2:N$57) -> 1 | P28: =IF(M28="YES",L28,IF(O28>40,L28-1,L28)) -> 3
A29: Creative Data | B29: 2 | C29: 3 | D29: 3 | E29: 3 | F29: 0.3 | G29: 0.4 | H29: 0.15 | I29: 0.15 | J29: =B29*F29+C29*G29+D29*H29+E29*I29 -> 2.7 | K29: =J29*2 -> 5.4 | L29: =IF(K29<=3,2,IF(K29<=7,3,4)) -> 3 | M29: =IF(OR(A29="Pancasila",A29="Kewarganegaraan",A29="Bahasa Inggris",LEFT(A29,3)="PAI"),"YES","NO") -> NO | N29: =(E29*I29)+(D29*H29)+(C29*G29)+(B29*F29) -> 2.7 | O29: =RANK(N29,N$2:N$57) -> 1 | P29: =IF(M29="YES",L29,IF(O29>40,L29-1,L29)) -> 3
A30: PAI 5 | B30: 2 | C30: 2 | D30: 2 | E30: 2 | F30: 0.3 | G30: 0.4 | H30: 0.15 | I30: 0.15 | J30: =B30*F30+C30*G30+D30*H30+E30*I30 -> 2 | K30: =J30*2 -> 4 | L30: =IF(K30<=3,2,IF(K30<=7,3,4)) -> 3 | M30: =IF(OR(A30="Pancasila",A30="Kewarganegaraan",A30="Bahasa Inggris",LEFT(A30,2)="PAI"),"YES","NO") -> NO | N30: =(E30*I30)+(D30*H30)+(C30*G30)+(B30*F30) -> 2 | O30: =RANK(N30,N$2:N$57) -> 47 | P30: =IF(M30="YES",L30,IF(O30>40,L30-1,L30)) -> 2
A31: Ekonometrika Lanjut | B31: 2 | C31: 3 | D31: 3 | E31: 3 | F31: 0.3 | G31: 0.4 | H31: 0.15 | I31: 0.15 | J31: =B31*F31+C31*G31+D31*H31+E31*I31 -> 2.7 | K31: =J31*2 -> 5.4 | L31: =IF(K31<=3,2,IF(K31<=7,3,4)) -> 3 | M31: =IF(OR(A31="Pancasila",A31="Kewarganegaraan",A31="Bahasa Inggris",LEFT(A31,3)="PAI"),"YES","NO") -> NO | N31: =(E31*I31)+(D31*H31)+(C31*G31)+(B31*F31) -> 2.7 | O31: =RANK(N31,N$2:N$57) -> 1 | P31: =IF(M31="YES",L31,IF(O31>40,L31-1,L31)) -> 3
A32: Metode Penelitian | B32: 2 | C32: 3 | D32: 3 | E32: 3 | F32: 0.3 | G32: 0.4 | H32: 0.15 | I32: 0.15 | J32: =B32*F32+C32*G32+D32*H32+E32*I32 -> 2.7 | K32: =J32*2 -> 5.4 | L32: =IF(K32<=3,2,IF(K32<=7,3,4)) -> 3 | M32: =IF(OR(A32="Pancasila",A32="Kewarganegaraan",A32="Bahasa Inggris",LEFT(A32,3)="PAI"),"YES","NO") -> NO | N32: =(E32*I32)+(D32*H32)+(C32*G32)+(B32*F32) -> 2.7 | O32: =RANK(N32,N$2:N$57) -> 1 | P32: =IF(M32="YES",L32,IF(O32>40,L32-1,L32)) -> 3
A33: Moneter | B33: 2 | C33: 3 | D33: 3 | E33: 3 | F33: 0.3 | G33: 0.4 | H33: 0.15 | I33: 0.15 | J33: =B33*F33+C33*G33+D33*H33+E33*I33 -> 2.7 | K33: =J33*2 -> 5.4 | L33: =IF(K33<=3,2,IF(K33<=7,3,4)) -> 3 | M33: =IF(OR(A33="Pancasila",A33="Kewarganegaraan",A33="Bahasa Inggris",LEFT(A33,3)="PAI"),"YES","NO") -> NO | N33: =(E33*I33)+(D33*H33)+(C33*G33)+(B33*F33) -> 2.7 | O33: =RANK(N33,N$2:N$57) -> 1 | P33: =IF(M33="YES",L33,IF(O33>40,L33-1,L33)) -> 3
A34: Internasional | B34: 2 | C34: 3 | D34: 3 | E34: 3 | F34: 0.3 | G34: 0.4 | H34: 0.15 | I34: 0.15 | J34: =B34*F34+C34*G34+D34*H34+E34*I34 -> 2.7 | K34: =J34*2 -> 5.4 | L34: =IF(K34<=3,2,IF(K34<=7,3,4)) -> 3 | M34: =IF(OR(A34="Pancasila",A34="Kewarganegaraan",A34="Bahasa Inggris",LEFT(A34,3)="PAI"),"YES","NO") -> NO | N34: =(E34*I34)+(D34*H34)+(C34*G34)+(B34*F34) -> 2.7 | O34: =RANK(N34,N$2:N$57) -> 1 | P34: =IF(M34="YES",L34,IF(O34>40,L34-1,L34)) -> 3
A35: Kependudukan | B35: 2 | C35: 3 | D35: 3 | E35: 3 | F35: 0.3 | G35: 0.4 | H35: 0.15 | I35: 0.15 | J35: =B35*F35+C35*G35+D35*H35+E35*I35 -> 2.7 | K35: =J35*2 -> 5.4 | L35: =IF(K35<=3,2,IF(K35<=7,3,4)) -> 3 | M35: =IF(OR(A35="Pancasila",A35="Kewarganegaraan",A35="Bahasa Inggris",LEFT(A35,3)="PAI"),"YES","NO") -> NO | N35: =(E35*I35)+(D35*H35)+(C35*G35)+(B35*F35) -> 2.7 | O35: =RANK(N35,N$2:N$57) -> 1 | P35: =IF(M35="YES",L35,IF(O35>40,L35-1,L35)) -> 3
A36: Lingkungan | B36: 2 | C36: 3 | D36: 3 | E36: 3 | F36: 0.3 | G36: 0.4 | H36: 0.15 | I36: 0.15 | J36: =B36*F36+C36*G36+D36*H36+E36*I36 -> 2.7 | K36: =J36*2 -> 5.4 | L36: =IF(K36<=3,2,IF(K36<=7,3,4)) -> 3 | M36: =IF(OR(A36="Pancasila",A36="Kewarganegaraan",A36="Bahasa Inggris",LEFT(A36,3)="PAI"),"YES","NO") -> NO | N36: =(E36*I36)+(D36*H36)+(C36*G36)+(B36*F36) -> 2.7 | O36: =RANK(N36,N$2:N$57) -> 1 | P36: =IF(M36="YES",L36,IF(O36>40,L36-1,L36)) -> 3
A37: Keuangan | B37: 2 | C37: 3 | D37: 3 | E37: 3 | F37: 0.3 | G37: 0.4 | H37: 0.15 | I37: 0.15 | J37: =B37*F37+C37*G37+D37*H37+E37*I37 -> 2.7 | K37: =J37*2 -> 5.4 | L37: =IF(K37<=3,2,IF(K37<=7,3,4)) -> 3 | M37: =IF(OR(A37="Pancasila",A37="Kewarganegaraan",A37="Bahasa Inggris",LEFT(A37,3)="PAI"),"YES","NO") -> NO | N37: =(E37*I37)+(D37*H37)+(C37*G37)+(B37*F37) -> 2.7 | O37: =RANK(N37,N$2:N$57) -> 1 | P37: =IF(M37="YES",L37,IF(O37>40,L37-1,L37)) -> 3
A38: PAI 6 | B38: 2 | C38: 2 | D38: 2 | E38: 2 | F38: 0.3 | G38: 0.4 | H38: 0.15 | I38: 0.15 | J38: =B38*F38+C38*G38+D38*H38+E38*I38 -> 2 | K38: =J38*2 -> 4 | L38: =IF(K38<=3,2,IF(K38<=7,3,4)) -> 3 | M38: =IF(OR(A38="Pancasila",A38="Kewarganegaraan",A38="Bahasa Inggris",LEFT(A38,2)="PAI"),"YES","NO") -> NO | N38: =(E38*I38)+(D38*H38)+(C38*G38)+(B38*F38) -> 2 | O38: =RANK(N38,N$2:N$57) -> 47 | P38: =IF(M38="YES",L38,IF(O38>40,L38-1,L38)) -> 2
A39: Perencanaan | B39: 2 | C39: 3 | D39: 3 | E39: 3 | F39: 0.3 | G39: 0.4 | H39: 0.15 | I39: 0.15 | J39: =B39*F39+C39*G39+D39*H39+E39*I39 -> 2.7 | K39: =J39*2 -> 5.4 | L39: =IF(K39<=3,2,IF(K39<=7,3,4)) -> 3 | M39: =IF(OR(A39="Pancasila",A39="Kewarganegaraan",A39="Bahasa Inggris",LEFT(A39,3)="PAI"),"YES","NO") -> NO | N39: =(E39*I39)+(D39*H39)+(C39*G39)+(B39*F39) -> 2.7 | O39: =RANK(N39,N$2:N$57) -> 1 | P39: =IF(M39="YES",L39,IF(O39>40,L39-1,L39)) -> 3
A40: Ekonomi Politik | B40: 2 | C40: 3 | D40: 3 | E40: 3 | F40: 0.3 | G40: 0.4 | H40: 0.15 | I40: 0.15 | J40: =B40*F40+C40*G40+D40*H40+E40*I40 -> 2.7 | K40: =J40*2 -> 5.4 | L40: =IF(K40<=3,2,IF(K40<=7,3,4)) -> 3 | M40: =IF(OR(A40="Pancasila",A40="Kewarganegaraan",A40="Bahasa Inggris",LEFT(A40,3)="PAI"),"YES","NO") -> NO | N40: =(E40*I40)+(D40*H40)+(C40*G40)+(B40*F40) -> 2.7 | O40: =RANK(N40,N$2:N$57) -> 1 | P40: =IF(M40="YES",L40,IF(O40>40,L40-1,L40)) -> 3
...

Sheet MK draft
A1: 20 April Jam 08.30 | G1: 20 Apri jam 11.30
A2: SEMESTER 1 | G2: SEMESTER 1 | L2: SEMESTER I/FIRST SEMESTER
A3: Kode Mata Kuliah | B3: Nama Mata Kuliah / Course Title | C3: SKS | G3: Kode Mata Kuliah | H3: Nama Mata Kuliah / Course Title | I3: SKS | L3: Kode Mata Kuliah | M3: Nama Mata Kuliah / Course Title | N3: Satuan Kredit Semester/Credit
A4: - | B4: Pengantar Ekonomi Mikro | C4: 3 | G4: - | H4: Pengantar Ekonomi Mikro | I4: 3 | L4: - | M4: Pengantar Ekonomi Mikro / Introduction to Microeconomics | N4: 3
A5: - | B5: Pengantar Ekonomi Makro | C5: 3 | G5: - | H5: Pengantar Ekonomi Makro | I5: 3 | L5: - | M5: Pengantar Ekonomi Makro / Introduction to Macroeconomics | N5: 3
A6: - | B6: Pengantar Bisnis | C6: 2 | G6: - | H6: Pengantar Bisnis | I6: 2 | L6: - | M6: Pengantar Bisnis / Introduction to Business | N6: 2
A7: - | B7: Matematika Ekonomi | C7: 3 | G7: - | H7: Matematika Ekonomi | I7: 3 | L7: - | M7: Matematika Ekonomi / Mathematical Economics | N7: 3
